Workbook
Name 切片器_裙长: #N/A

Sheet Sheet1
A3: 行标签 | B3: 计数项:30天销售额
A4: 广东广州 | B4: 67
A5: 浙江杭州 | B5: 39
A6: 北京 | B6: 5
A7: 江苏宿迁 | B7: 3
A8: 广东深圳 | B8: 2
A9: 广东中山 | B9: 2
A10: (空白) | B10: 1
A11: 所在地 | B11: 1
A12: 山东青岛 | B12: 1
A13: 江苏苏州 | B13: 1
A14: 广东肇庆 | B14: 1
A15: 广东东莞 | B15: 1
... A18: 总计 | B18: 126

Sheet Sheet2
A3: 行标签 | B3: 计数项:30天销售额 | C3: 平均值项:销售价
A4: 短裙 | B4: 47 | C4: 53.477021
A5: 裙长 | B5: 1 | C5: #DIV/0!
A6: 长裙 | B6: 24 | C6: 52.444583
A7: 中裙 | B7: 26 | C7: 66.523462
A8: 中长裙 | B8: 27 | C8: 37.618519
A9: (空白) | B9: 1
A10: 总计 | B10: 126 | C10: 52.559677

Sheet Sheet4
A3: 计数项:30天销售额 | B3: 列标签
A4: 行标签 | B4: 短裙 | C4: 中裙 | D4: 总计
A5: 北京 | C5: 1 | D5: 1
A6: 广东广州 | B6: 29 | C6: 13 | D6: 42
A7: 广东揭阳 | B7: 1 | D7: 1
A8: 广东深圳 | B8: 1 | C8: 1 | D8: 2
A9: 广东中山 | B9: 2 | D9: 2
A10: 江苏苏州 | C10: 1 | D10: 1
A11: 江苏宿迁 | B11: 2 | D11: 2
A12: 浙江杭州 | B12: 12 | C12: 10 | D12: 22
A13: 总计 | B13: 47 | C13: 26 | D13: 73

Sheet 源数据
A1: 数据下载时间：2015-08-23 18:09:46 功能：看店宝【kandianbao.com】 淘宝搜索排名查询 相关查询网址：http://so.kandianbao.com/连衣裙/ 查询条件：销量排序
A2: 序号 | B2: 排名位置 | C2: 宝贝名称：看店宝【kandianbao.com】 | D2: 货号 | E2: 原价 | F2: 折扣率 | G2: 销售价 | H2: 手机价 | I2: 库存 | J2: 邮费 | K2: 30天收货 | L2: 收货占比 | M2: 30天销量 | N2: 销量占比 | O2: 30天销售额 | P2: 销售额占比 | Q2: 总收藏量 | R2: PC总浏览量 | S2: 收藏比 | T2: 总分享数 | U2: 总评价数 | V2: 宝贝促销 | W2: 店铺促销 | X2: 活动促销 | Y2: 服务保证 | Z2: 所在地 | AA2: 店铺掌柜 | AB2: 开店日期 | AC2: 店铺信誉 | AD2: 店铺dsr | AE2: 店铺收藏 | AF2: 店铺类型 | AG2: 好评率 | AH2: 一级类目 | AI2: 二级类目 | AJ2: 三级类目 | AK2: 下架日期 | AL2: 下架时间 | AM2: 天数 | AN2: 星期 | AO2: 宝贝地址 | AP2: 分析地址 | AQ2: 组合形式 | AR2: 成分含量 | AS2: 廓形 | AT2: 领型 | AU2: 衣门襟 | AV2: 颜色分类 | AW2: 通勤 | AX2: 尺码 | AY2: 图案 | AZ2: 裙长 | BA2: 款式 | BB2: 销售渠道类型 | BC2: 面料 | BD2: 流行元素/工艺 | BE2: 货号 | BF2: 裙型 | BG2: 年份季节 | BH2: 材质成分 | BI2: 袖型 | BJ2: 品牌 | BK2: 风格 | BL2: 甜美 | BM2: 腰型 | BN2: 材质 | BO2: 街头 | BP2: 适用年龄 | BQ2: 袖长 | BR2: 评价标签
A3: 1 | B3: 第 1 页 第 1 位 | C3: 2015夏季新款韩版通勤女装圆领短袖气质修身ol连衣裙女中裙淑女裙 | E3: 468 | F3: 0.3342 | G3: 156.42 | H3: 156.42 | I3: 8011 | J3: 包邮 | K3: 21808 | L3: 0.0255 | M3: 30590 | N3: 0.027 | O3: 4784887.8 | P3: 0.0866 | Q3: 173404 | R3: 649367 | S3: 0.267 | T3: 21 | U3: 3096 | Y3: 8天退货，退货邮费买家承担|蚂蚁花呗|信用卡支付|集分宝|如实描述 | Z3: 浙江杭州 | AA3: 悠然1149 | AB3: 41953.842 | AC3: 2冠 | AD3: 4.8; 4.8; 4.8 | AE3: 36209 | AF3: 淘宝 | AG3: 0.9846 | AH3: 女装/女士精品 | AI3: 连衣裙 | AK3: 42240 | AL3: 0.92013889 | AM3: 1天3时55分15秒 | AN3: 一 | AO3: http://item.taobao.com/item.htm?id=520635131814 | AP3: http://item.kandianbao.com/520635131814/ | AQ3: 单件 | AR3: 81%(含)-90%(含) | AS3: H型 | AT3: 圆领 | AU3: 套头 | AV3: 粉红色 | AW3: 韩版 | AX3: S，M，L，XL，2XL | AY3: 纯色 | AZ3: 中裙 | BD3: 蝴蝶结，抽褶，口袋，系带，拉链 | BF3: 一步裙 | BG3: 2015年夏季 | BK3: 通勤 | BM3: 中腰 | BN3: 麻 | BQ3: 短袖 | BR3: 质量不错(20) ; 穿着漂亮(16) ; 做工不错(14) ; 板型很好(12) ; 服务好(11) ; 很舒适(11) ;
A4: 2 | B4: 第 1 页 第 2 位 | C4: 夏季连衣裙大码女装背心裙中长款包臀长裙内搭打底衫OL修身吊带裙 | D4: 6013- | E4: 104 | F4: 0.1827 | G4: 19 | H4: 19 | I4: 65359 | J4: 包邮 | K4: 21031 | L4: 0.0246 | M4: 35057 | N4: 0.0309 | O4: 666083 | P4: 0.0121 | Q4: 48530 | R4: 60393 | S4: 0.8036 | T4: 9 | U4: 3435 | Y4: 7天无理由|蚂蚁花呗|信用卡支付|集分宝|如实描述 | Z4: 广东东莞 | AA4: 物美价廉yy8 | AB4: 41705.55 | AC4: 1冠 | AD4: 4.6; 4.6; 4.5 | AE4: 2754 | AF4: 淘宝 | AG4: 0.9817 | AH4: 女装/女士精品 | AI4: 连衣裙 | AK4: 42244 | AL4: 0.63888889 | AM4: 4天21时10分15秒 | AN4: 五 | AO4: http://item.taobao.com/item.htm?id=45418797934 | AP4: http://item.kandianbao.com/45418797934/ | AQ4: 单件 | AR4: 31%(含)-50%(含) | AS4: A型 | AT4: V领 | AU4: 套头 | AV4: 玫红.，蓝色比图偏深，西瓜红偏橙色，浅绿比图偏浅，白色，黑色，酒红色，黄色 | AW4: OL风格 | AX4: L码建议105-120斤，M码建议90-105斤，XXL建议130-140，XL码建议120-130，XXXL建议140-155，S码建议75-90斤，买2件优惠3元，买3件优惠5元 | AY4: 纯色 | AZ4: 中长裙 | BA4: 其他/other | BC4: 针织 | BD4: 连衣裙夏季中长款包臀女长裙大码背心裙内搭打底衫韩版修身吊带裙，印花 | BE4: 6013- | BF4: 公主裙 | BG4: 2015年夏季 | BK4: 通勤 | BM4: 中腰 | BN4: 涤纶 | BP4: 25-29周岁 | BQ4: 无袖 | BR4: 很舒适(170) ; 宝贝很赞(113) ; 穿着漂亮(101) ; 版型好看(85) ; 衣服很合身(67) ; 颜色很美(41) ;
A5: 3 | B5: 第 1 页 第 3 位 | C5: 2015夏天新款显瘦牛仔背带裙连衣裙女装夏季潮学生牛仔背心短裙子 | E5: 192 | F5: 0.1198 | G5: 23 | H5: 23 | I5: 945466 | J5: 包邮 | K5: 20824 | L5: 0.0243 | M5: 25429 | N5: 0.0224 | O5: 584867 | P5: 0.0106 | Q5: 85198 | R5: 199658 | S5: 0.4267 | T5: 19 | U5: 15799 | Y5: 卖家承诺72小时内发货|8天退货，退货邮费买家承担|蚂蚁花呗|信用卡支付|集分宝|如实描述 | Z5: 广东中山 | AA5: 韩国专柜女装 | AB5: 41681.994 | AC5: 2冠 | AD5: 4.6; 4.6; 4.5 | AE5: 4594 | AF5: 淘宝 | AG5: 0.9637 | AH5: 女装/女士精品 | AI5: 连衣裙 | AK5: 42242 | AL5: 0.90228009 | AM5: 3天3时29分32秒 | AN5: 三 | AO5: http://item.taobao.com/item.htm?id=45428232575 | AP5: http://item.kandianbao.com/45428232575/ | AQ5: 单件 | AR5: 81%(含)-90%(含) | AV5: 裙子尺寸偏大，深蓝色 | AX5: XXS，XS，S，M，L，XL | AY5: 纯色 | AZ5: 短裙 | BA5: 背带 | BC5: 牛仔布 | BD5: 背带，纽扣 | BF5: 其他 | BG5: 2015年夏季 | BI5: 其他 | BJ5: 无 | BK5: 甜美 | BL5: 学院 | BM5: 宽松腰 | BN5: 醋纤 | BP5: 18-24周岁 | BQ5: 无袖 | BR5: 质量蛮好(2234) ; 版型漂亮(1276) ; 穿着效果好(1014) ; 大小合适(591) ; 衣服很舒服(541) ; 尺寸有偏差(221) ;
A6: 4 | B6: 第 1 页 第 4 位 | C6: 彩黛妃2015新款春夏季大码女装性感修身短袖镂空衣领连衣裙韩版潮 | D6: C0070 | E6: 128 | F6: 0.1547 | G6: 19.8 | H6: 19.8 | I6: 733657 | J6: 包邮 | K6: 17668 | L6: 0.0206 | M6: 22725 | N6: 0.02 | O6: 449955 | P6: 0.0081 | Q6: 105162 | R6: - | S6: - | T6: 179 | U6: 38269 | Z6: 江苏宿迁 | AA6: 彩黛妃旗舰店 | AB6: 41723.451 | AC6: 1金冠 | AD6: 4.6; 4.6; 4.8 | AE6: 308260 | AF6: 天猫 | AG6: 1 | AH6: 女装/女士精品 | AI6: 连衣裙 | AK6: 42245 | AL6: 0.42803241 | AM6: 5天16时6分37秒 | AN6: 六 | AO6: http://item.taobao.com/item.htm?id=43944007169 | AP6: http://item.kandianbao.com/43944007169/ | AQ6: 单件 | AR6: 95%以上 | AT6: 圆领 | AU6: 套头 | AV6: 浅玫红，薄荷绿，浅兰色，黑色 | AW6: 韩版 | AX6: S，M，L，XL，XXL | AY6: 纯色 | AZ6: 短裙 | BA6: 其他/other | BC6: 针织 | BD6: 褶皱 | BE6: C0070 | BF6: A字裙 | BG6: 2015年夏季 | BH6: 聚酯纤维94.8% 聚氨酯弹性纤维(氨纶)5.2% | BI6: 其他 | BJ6: 彩黛妃 | BK6: 通勤 | BM6: 高腰 | BN6: 涤纶 | BP6: 25-29周岁 | BQ6: 短袖 | BR6: 质量蛮好(7231) ; 版型好看(5113) ; 穿着美(3353) ; 衣服很合身(2627) ; 颜色很好(1909) ; 物流太慢(582) ;
A7: 5 | B7: 第 1 页 第 5 位 | C7: 凤凤服饰2015夏装新款连衣裙夏裙纯色韩版宽松无袖显瘦遮住小肚腩 | D7: 99 | E7: 299 | F7: 0.099 | G7: 29.6 | H7: 29.6 | I7: 20259 | J7: 包邮 | K7: 17586 | L7: 0.0205 | M7: 18265 | N7: 0.0161 | O7: 540644 | P7: 0.0098 | Q7: 26748 | R7: 87202 | S7: 0.3067 | T7: 2 | U7: 6214 | Y7: 7天无理由|蚂蚁花呗|信用卡支付|集分宝|如实描述 | Z7: 广东广州 | AA7: ff2012888 | AB7: 40990.534 | AC7: 2冠 | AD7: 4.0; 4.1; 4.0 | AE7: 3680 | AF7: 淘宝 | AG7: 0.8931 | AH7: 女装/女士精品 | AI7: 连衣裙 | AK7: 42243 | AL7: 0.96678241 | AM7: 4天5时2分25秒 | AN7: 四 | AO7: http://item.taobao.com/item.htm?id=520565996333 | AP7: http://item.kandianbao.com/520565996333/ | AQ7: 单件 | AR7: 81%(含)-90%(含) | AS7: A型 | AT7: 圆领 | AU7: 套头 | AV7: 活动马上结束涨价，粉红色 | AX7: S，M，L，XL，2XL | AY7: 纯色 | AZ7: 中长裙 | BA7: 其他/other | BC7: 其他 | BE7: 99 | BF7: A字裙 | BG7: 2015年夏季 | BI7: 蝙蝠袖 | BK7: 街头 | BM7: 宽松腰 | BN7: 棉 | BO7: 欧美 | BQ7: 无袖 | BR7: 很舒服(66) ; 质量蛮好(50) ; 版型漂亮(49) ; 划算(44) ; 穿着美(36) ; 衣服蛮薄(9) ;
A8: 6 | B8: 第 1 页 第 6 位 | C8: 2015夏装新款中老年女装印花连衣裙夏季大码修身中年妈妈装碎花裙 | D8: 136 | E8: 88 | F8: 0.1789 | G8: 15.74 | H8: 15.74 | I8: 5830 | J8: 包邮 | K8: 16114 | L8: 0.0188 | M8: 31284 | N8: 0.0276 | O8: 492410.16 | P8: 0.0089 | Q8: 35684 | R8: 763048 | S8: 0.0468 | T8: 277 | U8: 25728 | Y8: 卖家承诺72小时内发货|7天无理由|蚂蚁花呗|信用卡支付|集分宝|如实描述 | Z8: 北京 | AA8: 酷奇宝贝stb | AB8: 40423.859 | AC8: 4冠 | AD8: 4.7; 4.7; 4.7 | AE8: 13776 | AF8: 淘宝 | AG8: 0.9734 | AH8: 女装/女士精品 | AI8: 连衣裙 | AK8: 42239 | AL8: 0.9153588 | AM8: 0.15858796 | AN8: 日 | AO8: http://item.taobao.com/item.htm?id=24393792120 | AP8: http://item.kandianbao.com/24393792120/ | AQ8: 单件 | AR8: 81%(含)-90%(含) | AT8: V领 | AV8: 20号色，15号色，19号色，12号色，11号色，5号色，26号色，25号色，23号色，27号色，22号色，28号色，1号色，3号色，2号色，8号色，21号色，13号色，16号色，17号色，18号色 | AX8: XL建议体重100-115，3XL建议体重125-135，2XL建议体重115-125，4XL建议体重135-145，L建议体重80-100，5XL建议体重145-160 | AY8: 碎花 | AZ8: 中长裙 | BD8: 3D，印花 | BE8: 136 | BF8: 大摆型 | BG8: 2015年夏季 | BI8: 花瓣袖 | BK8: 通勤 | BP8: 30-34周岁 | BQ8: 短袖 | BR8: 质量不错(2883) ; 衣衣很舒服(1857) ; 人群(1838) ; 版型漂亮(1484) ; 穿上好看(962) ; 码数不合(586) ;
A9: 7 | B9: 第 1 页 第 7 位 | C9: 韩国2015春夏季新款女装高腰两件套连衣裙 夏装蓬蓬a字裙短袖套装 | E9: 109 | F9: 0.2661 | G9: 29 | H9: 29 | I9: 1470592 | J9: 包邮 | K9: 14988 | L9: 0.0175 | M9: 25069 | N9: 0.0221 | O9: 727001 | P9: 0.0132 | Q9: 62724 | R9: 55138 | S9: 1.1376 | T9: 2 | U9: 770 | Y9: 卖家承诺20小时内发货|7天无理由|集分宝|支付宝支付|如实描述 | Z9: 广东广州 | AA9: 人生朱1448200051 | AB9: 42183.855 | AC9: 3钻 | AD9: 4.4; 4.4; 4.2 | AE9: 8594 | AF9: 淘宝 | AG9: 0.9627 | AH9: 女装/女士精品 | AI9: 连衣裙 | AK9: 42239 | AL9: 0.88596065 | AM9: 0.12918981 | AN9: 日 | AO9: http://item.taobao.com/item.htm?id=520347387757 | AP9: http://item.kandianbao.com/520347387757/ | AQ9: 两件套 | AR9: 71%(含)-80%(含) | AS9: A型 | AT9: 圆领 | AU9: 套头 | AV9: 单件上衣，单件裙子，上衣+裙子 | AW9: 复古 | AX9: S，M，L，XL，2XL | AZ9: 短裙 | BA9: 其他/other | BC9: 欧根纱 | BD9: 拼接，蕾丝，印花 | BF9: A字裙 | BG9: 2015年夏季 | BI9: 常规 | BJ9: 无 | BK9: 通勤 | BM9: 高腰 | BN9: 涤纶 | BP9: 18-24周岁 | BQ9: 短袖 | BR9: 衣服不错(37) ; 版型好(29) ; 很划算(19) ; 态度不错(17) ; 快递不错(16) ; 很舒服(12) ;
A10: 8 | B10: 第 1 页 第 8 位 | C10: 2015夏季新品女装 韩版可爱卡通米奇印花开叉中长款短袖T恤连衣裙 | E10: 89 | F10: 0.2022 | G10: 18 | H10: 18 | I10: 2489091 | J10: 包邮 | K10: 13841 | L10: 0.0162 | M10: 18282 | N10: 0.0161 | O10: 329076 | P10: 0.006 | Q10: 38864 | R10: 29307 | S10: 1.3261 | T10: 2 | U10: 5834 | Y10: 7天无理由|蚂蚁花呗|信用卡支付|集分宝|如实描述 | Z10: 广东广州 | AA10: 韩衣馆shop | AB10: 41571.557 | AC10: 3冠 | AD10: 4.7; 4.7; 4.7 | AE10: 10680 | AF10: 淘宝 | AG10: 0.9749 | AH10: 女装/女士精品 | AI10: 连衣裙 | AK10: 42240 | AL10: 0.65258102 | AM10: 0.89581019 | AN10: 一 | AO10: http://item.taobao.com/item.htm?id=520221451671 | AP10: http://item.kandianbao.com/520221451671/ | AQ10: 单件 | AR10: 31%(含)-50%(含) | AT10: 圆领 | AU10: 套头 | AV10: 白色，黑色 | AW10: 韩版 | AX10: 均码（优质正品），均码（普通起球），S（优质正品），M（优质正品），L（优质正品），XL（优质正品），XXL（优质正品），3XL（优质正品），4XL（优质正品），5XL（优质正品），6XL（优质正品），优质质量超好，质量问题包退，收藏送礼物，100%不起球不掉色，预售款28号出 | AY10: 卡通动漫 | AZ10: 长裙 | BA10: 其他/other | BC10: 其他 | BD10: 拼接，印花 | BF10: 其他 | BG10: 2015年夏季 | BI10: 常规 | BK10: 通勤 | BM10: 高腰 | BN10: 其他 | BP10: 18-24周岁 | BQ10: 短袖 | BR10: 衣服很舒服(464) ; 整体不错(414) ; 版型漂亮(157) ; 穿着效果好(156) ; 布料好(108) ; 大小合适(87) ;
A11: 9 | B11: 第 1 页 第 9 位 | C11: 2015夏装新款套装甜美两件套女装裙子 欧洲站夏季短裙雪纺连衣裙 | E11: 118 | F11: 0.322 | G11: 38 | H11: 38 | I11: 12720 | J11: 包邮 | K11: 12729 | L11: 0.0149 | M11: 14498 | N11: 0.0128 | O11: 550924 | P11: 0.01 | Q11: 111246 | R11: 654964 | S11: 0.1699 | T11: 68 | U11: 15242 | Y11: 卖家承诺72小时内发货|8天退货，退货邮费买家承担|蚂蚁花呗|信用卡支付|集分宝|如实描述 | Z11: 广东广州 | AA11: wanwalkerman | AB11: 41112.482 | AC11: 5冠 | AD11: 4.7; 4.7; 4.6 | AE11: 139674 | AF11: 淘宝 | AG11: 0.9849 | AH11: 女装/女士精品 | AI11: 连衣裙 | AK11: 42239 | AL11: 0.95984954 | AM11: 0.2030787 | AN11: 日 | AO11: http://item.taobao.com/item.htm?id=45756314177 | AP11: http://item.kandianbao.com/45756314177/ | AQ11: 两件套 | AT11: 圆领 | AU11: 拉链 | AV11: 白色（一套），单件上衣，提示：马上涨价 | AX11: S，M，L，XL，2XL | AY11: 碎花 | AZ11: 短裙 | BC11: 雪纺 | BD11: 印花 | BF11: 公主裙 | BG11: 2015年夏季 | BI11: 常规 | BJ11: 三号线女装 | BK11: 甜美 | BL11: 公主 | BM11: 中腰 | BQ11: 短袖 | BR11: 板型很好(1890) ; 质量蛮好(1833) ; 穿着美(875) ; 很舒服(818) ; 码子很准(704) ; 质量不行(187) ;
A12: 10 | B12: 第 1 页 第 10 位 | C12: 2015夏装新款韩版连衣裙背心裙修身高腰条纹小香风打底裙蓬蓬裙潮 | D12: 0 | E12: 64 | F12: 0.3594 | G12: 23 | H12: 23 | I12: 1554 | J12: 包邮 | K12: 12668 | L12: 0.0148 | M12: 15400 | N12: 0.0136 | O12: 354200 | P12: 0.0064 | Q12: 41830 | R12: 104826 | S12: 0.399 | T12: 5 | U12: 2857 | Y12: 8天退货，退货邮费买家承担|蚂蚁花呗|信用卡支付|集分宝|如实描述 | Z12: 广东广州 | AA12: 美丽呼吸韩版女装 | AB12: 41945.814 | AC12: 1冠 | AD12: 4.7; 4.7; 4.6 | AE12: 3932 | AF12: 淘宝 | AG12: 0.9802 | AH12: 女装/女士精品 | AI12: 连衣裙 | AK12: 42241 | AL12: 0.9172338 | AM12: 2天3时51分4秒 | AN12: 二 | AO12: http://item.taobao.com/item.htm?id=520487212484 | AP12: http://item.kandianbao.com/520487212484/ | AQ12: 单件 | AR12: 81%(含)-90%(含) | AU12: 套头 | AV12: 商城优质版不起球，普通版偏短偏小，普通版轻微起球，请购买商城优质版 | AW12: 韩版 | AX12: XXL，提示：面料有弹性，S，M，L，XL | AY12: 条纹 | AZ12: 短裙 | BA12: 其他/other | BD12: 拼接 | BE12: 0 | BF12: 公主裙 | BG12: 2015年夏季 | BJ12: 无 | BK12: 通勤 | BM12: 高腰 | BN12: 其他 | BP12: 18-24周岁 | BR12: 质量好(64) ; 很便宜(53) ; 版型好(53) ; 衣衣很舒服(43) ; 穿上好看(33) ; 尺寸很准(24) ;
A13: 11 | B13: 第 1 页 第 11 位 | C13: 2015新雪纺连衣裙大码女装夏装淑女超长款裙子显瘦气质连衣长裙夏 | D13: QDY15B4018 | E13: 103 | F13: 0.5631 | G13: 58 | H13: 58 | I13: 4545 | J13: 包邮 | K13: 11097 | L13: 0.013 | M13: 13899 | N13: 0.0123 | O13: 806142 | P13: 0.0146 | Q13: 71664 | R13: - | S13: - | T13: 20 | U13: 18384 | Z13: 广东广州 | AA13: 迪悠旗舰店 | AB13: 41478.726 | AC13: 4冠 | AD13: 4.8; 4.8; 4.8 | AE13: 51366 | AF13: 天猫 | AG13: 1 | AH13: 女装/女士精品 | AI13: 连衣裙 | AK13: 42242 | AL13: 0.72231481 | AM13: 2天23时10分23秒 | AN13: 三 | AO13: http://item.taobao.com/item.htm?id=45728286943 | AP13: http://item.kandianbao.com/45728286943/ | AQ13: 其他 | AR13: 95%以上 | AT13: 圆领 | AU13: 套头 | AV13: 酒红色，黑色 | AW13: 淑女 | AX13: S，M，L，XL，2XL，3XL，4XL，5XL | AY13: 纯色 | AZ13: 长裙 | BA13: 其他/other | BB13: 纯电商(只在线上销售) | BC13: 雪纺 | BD13: 蝴蝶结，镂空，系带 | BE13: QDY15B4018 | BF13: 不规则裙 | BG13: 2015年夏季 | BH13: 聚酯纤维100% | BI13: 衬衫袖 | BJ13: 迪悠 | BK13: 通勤 | BM13: 高腰 | BN13: 涤纶 | BP13: 25-29周岁 | BQ13: 短袖 | BR13: 衣服不错(3789) ; 穿着效果好(3322) ; 式样好(2915) ; 衣服很舒服(1824) ; 颜色挺正(1338) ; 做工一般(269) ;
A14: 12 | B14: 第 1 页 第 12 位 | C14: 韩国代购2015夏季新款女装纯棉麻短袖衬衫裙中长款甜美连衣裙子 | D14: WQ057 | E14: 428 | F14: 0.0751 | G14: 32.14 | H14: 32.14 | I14: 10597 | J14: 包邮 | K14: 10980 | L14: 0.0128 | M14: 11642 | N14: 0.0103 | O14: 374173.88 | P14: 0.0068 | Q14: 49080 | R14: 58539 | S14: 0.8384 | T14: 3 | U14: 4712 | Y14: 7天无理由|蚂蚁花呗|信用卡支付|集分宝|如实描述 | Z14: 浙江杭州 | AA14: 普拉达8606 | AB14: 40356.066 | AC14: 1冠 | AD14: 4.7; 4.7; 4.6 | AE14: 2128 | AF14: 淘宝 | AG14: 0.948 | AH14: 女装/女士精品 | AI14: 连衣裙 | AK14: 42241 | AL14: 0.87515046 | AM14: 2天2时50分28秒 | AN14: 二 | AO14: http://item.taobao.com/item.htm?id=520178820639 | AP14: http://item.kandianbao.com/520178820639/ | AQ14: 单件 | AR14: 51%(含)-70%(含) | AS14: H型 | AT14: POLO领 | AU14: 单排扣 | AV14: 即将涨价，浅蓝色 | AW14: 韩版 | AX14: S，M，L，XL | AY14: 条纹 | AZ14: 中裙 | BE14: WQ057 | BF14: A字裙 | BG14: 2015年夏季 | BI14: 常规 | BJ14: werokee | BK14: 通勤 | BM14: 高腰 | BN14: 棉 | BQ14: 短袖 | BR14: 整体不错(214) ; 版式好(168) ; 穿着效果好(115) ; 衣服很舒服(72) ; 尺码很准(56) ; 颜色挺正(54) ;
A15: 13 | B15: 第 1 页 第 13 位 | C15: 2015夏装女装长裙子夏季中长款拼接修身大码优雅印花雪纺连衣裙女 | D15: 2YF001-1213 | E15: 498 | F15: 0.0596 | G15: 29.7 | H15: 29.7 | I15: 102289 | J15: 5 | K15: 10964 | L15: 0.0128 | M15: 14074 | N15: 0.0124 | O15: 417997.8 | P15: 0.0076 | Q15: 54144 | R15: - | S15: - | T15: 10 | U15: 10971 | W15: 满3件，享包邮，送3元优惠券 | Z15: 浙江杭州 | AA15: 漫兰飘香旗舰店 | AB15: 41746.487 | AC15: 4冠 | AD15: 4.6; 4.6; 4.8 | AE15: 45399 | AF15: 天猫 | AG15: 1 | AH15: 女装/女士精品 | AI15: 连衣裙 | AK15: 42244 | AL15: 0.66400463 | AM15: 4天21时46分25秒 | AN15: 五 | AO15: http://item.taobao.com/item.htm?id=45622403217 | AP15: http://item.kandianbao.com/45622403217/ | AQ15: 单件 | AR15: 95%以上 | AS15: A型 | AT15: 圆领 | AU15: 套头 | AV15: 白色，粉花，黄花 | AW15: 淑女 | AX15: M，L，XL，2XL，3XL，4XL，5XL | AY15: 碎花 | AZ15: 中长裙 | BA15: 其他/other | BB15: 纯电商(只在线上销售) | BC15: 雪纺 | BD15: 蝴蝶结，荷叶边，抽褶，褶皱，纱网，拉链，印花 | BE15: 2YF001-1213 | BF15: 公主裙 | BG15: 2015年夏季 | BH15: 聚酯纤维100% | BI15: 常规 | BJ15: 漫兰飘香 | BK15: 通勤 | BM15: 高腰 | BN15: 涤纶 | BP15: 25-29周岁 | BQ15: 短袖 | BR15: 整体不错(1854) ; 版型好看(1297) ; 很舒服(785) ; 穿着美(623) ; 衣服很合身(589) ; 不合身(296) ;
A16: 14 | B16: 第 1 页 第 14 位 | C16: 棉麻连衣裙女2015夏季韩版学生小清新短袖中裙女文艺范亚麻裙子潮 | E16: 138 | F16: 0.2246 | G16: 31 | H16: 31 | I16: 50031 | J16: 包邮 | K16: 10740 | L16: 0.0125 | M16: 12348 | N16: 0.0109 | O16: 382788 | P16: 0.0069 | Q16: 60956 | R16: 119568 | S16: 0.5098 | T16: 7 | U16: 6754 | Y16: 10天退货，退货邮费买家承担|蚂蚁花呗|信用卡支付|集分宝|如实描述 | Z16: 浙江杭州 | AA16: 潮流女装62 | AB16: 41300.351 | AC16: 2冠 | AD16: 4.6; 4.7; 4.6 | AE16: 6812 | AF16: 淘宝 | AG16: 0.9722 | AH16: 女装/女士精品 | AI16: 连衣裙 | AK16: 42240 | AL16: 0.875 | AM16: 1天2时50分15秒 | AN16: 一 | AO16: http://item.taobao.com/item.htm?id=520101954838 | AP16: http://item.kandianbao.com/520101954838/ | AQ16: 单件 | AR16: 71%(含)-80%(含) | AS16: A型 | AT16: 圆领 | AU16: 套头 | AV16: 浅蓝色（优质版），粉红色(优质版），藏青色（优质版），粉红色，浅蓝色，藏青色 | AX16: S，M，L，XL | AY16: 格子 | AZ16: 中裙 | BC16: 织锦 | BD16: 蝴蝶结，系带 | BF16: A字裙 | BG16: 2015年夏季 | BI16: 常规 | BK16: 甜美 | BL16: 日系 | BM16: 中腰 | BN16: 麻 | BP16: 18-24周岁 | BQ16: 短袖 | BR16: 宝贝很赞(617) ; 外形好看(396) ; 很舒适(349) ; 穿着漂亮(279) ; 料子不错(177) ; 码数很准(161) ;
A17: 15 | B17: 第 1 页 第 15 位 | C17: jto 新款印花雪纺连衣裙夏喇叭袖松紧收腰显瘦短裙a字裙女062325 | E17: 87 | F17: 0.8 | G17: 69.6 | H17: 69.6 | I17: 1530 | J17: 包邮 | K17: 10634 | L17: 0.0124 | M17: 11950 | N17: 0.0105 | O17: 831720 | P17: 0.0151 | Q17: 120364 | R17: 252509 | S17: 0.4767 | T17: 4 | U17: 9848 | W17: 1.单笔订单满199元免运费(不包邮地区：内蒙古;黑龙江;甘肃;青海;新疆;西藏;台湾;香港;澳门;海外)，亲，快下手吧！ | Y17: 卖家承诺10天内发货|7天无理由|蚂蚁花呗|信用卡支付|集分宝|如实描述 | Z17: 浙江杭州 | AA17: zjforeverxxxx | AB17: 39643.925 | AC17: 2金冠 | AD17: 4.6; 4.7; 4.7 | AE17: 1458842 | AF17: 淘宝 | AG17: 0.9882 | AH17: 女装/女士精品 | AI17: 连衣裙 | AK17: 42239 | AL17: 0.92184028 | AM17: 0.16506944 | AN17: 日 | AO17: http://item.taobao.com/item.htm?id=520200646708 | AP17: http://item.kandianbao.com/520200646708/ | AQ17: 单件 | AR17: 81%(含)-90%(含) | AT17: 圆领 | AU17: 套头 | AV17: 白色，黑色 | AX17: S，M，L，XL | AY17: 花色 | AZ17: 短裙 | BA17: 其他/other | BC17: 雪纺 | BD17: 印花 | BF17: 其他 | BG17: 2015年夏季 | BI17: 喇叭袖 | BK17: 甜美 | BL17: 公主 | BM17: 松紧腰 | BP17: 18-24周岁 | BQ17: 五分袖 | BR17: 版型好(911) ; 宝贝很赞(688) ; 穿上好看(638) ; 衣衣很舒服(256) ; 尺寸很准(174) ; 发货服务差(76) ;
A18: 16 | B18: 第 1 页 第 16 位 | C18: 2015夏季新款小香风条纹胖MM背心连衣裙宽松大码蓬蓬裙高腰娃娃衫 | E18: 262 | F18: 0.0916 | G18: 24 | H18: 24 | I18: 457803 | J18: 包邮 | K18: 10333 | L18: 0.0121 | M18: 11330 | N18: 0.01 | O18: 271920 | P18: 0.0049 | Q18: 66934 | R18: 44914 | S18: 1.4903 | T18: 3 | U18: 2226 | Y18: 7天无理由|蚂蚁花呗|信用卡支付|集分宝|如实描述 | Z18: 广东广州 | AA18: 小小盼z | AB18: 41568.556 | AC18: 3冠 | AD18: 4.4; 4.5; 4.4 | AE18: 12566 | AF18: 淘宝 | AG18: 0.9443 | AH18: 女装/女士精品 | AI18: 连衣裙 | AK18: 42245 | AL18: 0.9190162 | AM18: 6天3时53分38秒 | AN18: 六 | AO18: http://item.taobao.com/item.htm?id=520448498247 | AP18: http://item.kandianbao.com/520448498247/ | AQ18: 单件 | AR18: 81%(含)-90%(含) | AT18: 圆领 | AU18: 拉链 | AV18: 图片色 优质布料，图片色 普通布料 | AW18: 淑女 | AX18: S，M，L，XL，2XL | AY18: 条纹 | AZ18: 中长裙 | BA18: 其他/other | BC18: 绸缎 | BD18: 蝴蝶结，树脂固色，蕾丝 | BF18: 大摆型 | BG18: 2015年夏季 | BI18: 蝙蝠袖 | BK18: 通勤 | BM18: 中腰 | BN18: 棉 | BP18: 18-24周岁 | BQ18: 无袖 | BR18: 整体不错(49) ; 版型好看(38) ; 衣服很舒服(29) ; 穿着效果好(25) ; 很划算(18) ; 快递不错(16) ;
A19: 17 | B19: 第 1 页 第 17 位 | C19: 2015韩系小清新套装连衣裙女春夏白领拼接两件套装裙吊带背心裙潮 | D19: fashion326 | E19: 127 | F19: 0.2126 | G19: 27 | H19: 27 | I19: 185972 | J19: 包邮 | K19: 10281 | L19: 0.012 | M19: 12390 | N19: 0.0109 | O19: 334530 | P19: 0.0061 | Q19: 85032 | R19: 77105 | S19: 1.1028 | T19: 9 | U19: 5282 | W19: 1.单笔订单满10元免运费(不包邮地区：台湾;香港;澳门;海外)，亲，快下手吧！|2.单笔订单满88元减4元；减后满88元，免运费(不包邮地区：台湾;香港;澳门;海外)，亲，快下手吧！|3.单笔订单满168元减8元；减后满168元，免运费(不包邮地区：台湾;香港;澳门;海外)，亲，快下手吧！|4.单笔订单满328元减16元；减后满328元，免运费(不包邮地区：台湾;香港;澳门;海外)，亲，快下手吧！|5.单笔订单满528元减20元；减后满528元，免运费(不包邮地区：台湾;香港;澳门;海外)，亲，快下手吧！ | Y19: 8天退货，退货邮费买家承担|蚂蚁花呗|信用卡支付|集分宝|如实描述 | Z19: 浙江杭州 | AA19: fashion时尚依馆 | AB19: 41620.015 | AC19: 3冠 | AD19: 4.6; 4.7; 4.6 | AE19: 31264 | AF19: 淘宝 | AG19: 0.9858 | AH19: 女装/女士精品 | AI19: 连衣裙 | AK19: 42245 | AL19: 0.875 | AM19: 6天2时50分15秒 | AN19: 六 | AO19: http://item.taobao.com/item.htm?id=45449529737 | AP19: http://item.kandianbao.com/45449529737/ | AQ19: 两件套 | AR19: 95%以上 | AT19: V领 | AU19: 套头 | AV19: 单件罩衫，图片色 两件套，单条黑背心 | AW19: 韩版 | AX19: 质量保证，限今特价，S，M，L，XL，2XL | AY19: 纯色 | AZ19: 中长裙 | BA19: 其他/other | BC19: 织锦 | BE19: fashion326 | BF19: 铅笔裙 | BG19: 2015年夏季 | BI19: 常规 | BJ19: fashion | BK19: 通勤 | BM19: 中腰 | BN19: 棉 | BQ19: 短袖 | BR19: 质量蛮好(640) ; 很舒服(408) ; 穿着美(350) ; 式样好(330) ; 尺码很好(187) ; 质量不行(35) ;
A20: 18 | B20: 第 1 页 第 18 位 | C20: 2015夏季包臀莫代尔长裙连衣裙大码吊带修身打底背心裙长款长裙 | E20: 89 | F20: 0.3247 | G20: 28.9 | H20: 28.9 | I20: 173717 | J20: 包邮 | K20: 10127 | L20: 0.0118 | M20: 13577 | N20: 0.012 | O20: 392375.3 | P20: 0.0071 | Q20: 29294 | R20: 57926 | S20: 0.5057 | T20: 9 | U20: 4994 | Y20: 卖家承诺72小时内发货|7天无理由|蚂蚁花呗|信用卡支付|集分宝|如实描述 | Z20: 浙江杭州 | AA20: 名款城 | AB20: 40771.765 | AC20: 3冠 | AD20: 4.8; 4.8; 4.7 | AE20: 12999 | AF20: 淘宝 | AG20: 0.9874 | AH20: 女装/女士精品 | AI20: 连衣裙 | AK20: 42241 | AL20: 0.67261574 | AM20: 1天21时58分49秒 | AN20: 二 | AO20: http://item.taobao.com/item.htm?id=520135988843 | AP20: http://item.kandianbao.com/520135988843/ | AQ20: 单件 | AR20: 51%(含)-70%(含) | AS20: H型 | AT20: 圆领 | AU20: 套头 | AV20: 黑色（大裙摆），深灰（大裙摆），浅灰（大裙摆），黑色（小裙摆款），深灰（小裙摆款），浅灰（小裙摆款） | AW20: 韩版 | AX20: S，M，L，XL，2XL | AY20: 纯色 | AZ20: 长裙 | BA20: 吊带 | BC20: 其他 | BF20: 一步裙 | BG20: 2015年夏季 | BI20: 其他 | BK20: 通勤 | BM20: 高腰 | BN20: 莫代尔 | BP20: 18-24周岁 | BQ20: 无袖 | BR20: 衣服很舒服(573) ; 质量蛮好(541) ; 穿着效果好(430) ; 版式好(207) ; 尺码很准(204) ; 衣服蛮薄(51) ;
A21: 19 | B21: 第 1 页 第 19 位 | C21: 两件套连衣裙欧洲站2015夏装新款套装雪纺裙子背心休闲短裙气质潮 | E21: 128 | F21: 0.2891 | G21: 37 | H21: 37 | I21: 680 | J21: 包邮 | K21: 8894 | L21: 0.0104 | M21: 12223 | N21: 0.0108 | O21: 452251 | P21: 0.0082 | Q21: 43082 | R21: 78608 | S21: 0.5481 | T21: 2 | U21: 1137 | Y21: 卖家承诺72小时内发货|8天退货，退货邮费买家承担|蚂蚁花呗|信用卡支付|集分宝|如实描述 | Z21: 广东广州 | AA21: 随心良品 | AB21: 41426.388 | AC21: 4冠 | AD21: 4.8; 4.8; 4.8 | AE21: 23117 | AF21: 淘宝 | AG21: 0.9846 | AH21: 女装/女士精品 | AI21: 连衣裙 | AK21: 42242 | AL21: 0.9587963 | AM21: 3天4时50分55秒 | AN21: 三 | AO21: http://item.taobao.com/item.htm?id=520523704111 | AP21: http://item.kandianbao.com/520523704111/ | AQ21: 两件套 | AR21: 81%(含)-90%(含) | AS21: A型 | AT21: 圆领 | AU21: 一粒扣 | AV21: 单件裙子，单件雪纺背心，上衣+短裙套装，提示：马上停产哦 | AX21: S【优质加内衬】，M【优质加内衬】，L【优质加内衬】 | AY21: 抽象图案 | AZ21: 短裙 | BA21: 吊带 | BC21: 雪纺 | BD21: 拼接，纽扣，拉链，印花 | BF21: A字裙 | BG21: 2015年夏季 | BI21: 常规 | BK21: 街头 | BM21: 高腰 | BN21: 其他 | BO21: 欧美 | BP21: 25-29周岁 | BQ21: 无袖 | BR21: 衣服不错(37) ; 穿着效果好(17) ; 版型漂亮(16) ; 便宜(11) ; 服务态度好(9) ; 衣服很舒服(8) ;
A22: 20 | B22: 第 1 页 第 20 位 | C22: 欧洲站2015夏装新款真丝雪纺水墨印花连衣裙收腰显瘦女裙子欧货 | D22: MY008 | E22: 988 | F22: 0.1615 | G22: 159.6 | H22: 159.6 | I22: 651 | J22: 包邮 | K22: 8733 | L22: 0.0102 | M22: 9760 | N22: 0.0086 | O22: 1557696 | P22: 0.0282 | Q22: 73194 | R22: 690856 | S22: 0.1059 | T22: 22 | U22: 5051 | Y22: 卖家承诺30天内发货|7天无理由|蚂蚁花呗|信用卡支付|集分宝|如实描述 | Z22: 浙江杭州 | AA22: zywj16叶伟林 | AB22: 39874.802 | AC22: 3冠 | AD22: 4.7; 4.8; 4.7 | AE22: 55049 | AF22: 淘宝 | AG22: 0.9758 | AH22: 女装/女士精品 | AI22: 连衣裙 | AK22: 42242 | AL22: 0.84722222 | AM22: 3天2时10分15秒 | AN22: 三 | AO22: http://item.taobao.com/item.htm?id=520386051081 | AP22: http://item.kandianbao.com/520386051081/ | AQ22: 单件 | AR22: 31%(含)-50%(含) | AS22: H型 | AT22: 圆领 | AU22: 单排扣 | AV22: 淡雅蓝 | AW22: 韩版 | AX22: S，M，L，XL，2XL | AY22: 花色 | AZ22: 中裙 | BA22: 其他/other | BC22: 雪纺 | BD22: 荷叶边，抽褶，印花 | BE22: MY008 | BF22: A字裙 | BG22: 2015年夏季 | BI22: 常规 | BK22: 通勤 | BM22: 宽松腰 | BN22: 其他 | BQ22: 七分袖 | BR22: 整体不错(42) ; 版型好(35) ; 尺寸很准(28) ; 很舒服(26) ; 穿着美(26) ; 颜色很好(17) ;
A23: 21 | B23: 第 1 页 第 21 位 | C23: 歌兔雪纺连衣裙夏季长裙2015夏装清仓特价修身显瘦中长款女装裙子 | D23: GT15CQZ69 | E23: 298 | F23: 0.2983 | G23: 88.9 | H23: 88.9 | I23: 8437 | J23: 包邮 | K23: 8355 | L23: 0.0098 | M23: 11294 | N23: 0.01 | O23: 1004036.6 | P23: 0.0182 | Q23: 145106 | R23: - | S23: - | T23: 130 | U23: 30222 | Z23: 浙江杭州 | AA23: 歌兔服饰旗舰店 | AB23: 41592.604 | AC23: 5冠 | AD23: 4.8; 4.8; 4.8 | AE23: 105194 | AF23: 天猫 | AG23: 1 | AH23: 女装/女士精品 | AI23: 连衣裙 | AK23: 42240 | AL23: 0.87575231 | AM23: 1天2时51分20秒 | AN23: 一 | AO23: http://item.taobao.com/item.htm?id=44548937074 | AP23: http://item.kandianbao.com/44548937074/ | AQ23: 单件 | AR23: 95%以上 | AT23: V领 | AU23: 套头 | AV23: 宝石蓝色，薄荷绿色，西瓜红，灰色，纯洁白色，嫩粉色，淡雅紫色，大红色，绿色，天空蓝色，淡黄色，魅力黑色 | AX23: S，M，L，XL，XXL，XS | AY23: 纯色 | AZ23: 长裙 | BA23: 其他/other | BC23: 雪纺 | BD23: 褶皱，拉链 | BE23: GT15CQZ69 | BF23: 大摆型 | BG23: 2015年夏季 | BH23: 新型聚酯纤维100% | BI23: 常规 | BJ23: 歌兔 | BK23: 通勤 | BM23: 中腰 | BN23: 其他 | BP23: 25-29周岁 | BQ23: 无袖 | BR23: 宝贝很赞(10561) ; 版型漂亮(6058) ; 穿着漂亮(5188) ; 很舒适(3834) ; 款式好看(3687) ; 物流慢(372) ;
A24: 22 | B24: 第 1 页 第 22 位 | C24: 2015夏季新款气质大码中裙文艺复古棉麻两件套连衣裙亚麻套装裙女 | E24: 144 | F24: 0.3056 | G24: 44 | H24: 44 | I24: 30212 | J24: 包邮 | K24: 8328 | L24: 0.0097 | M24: 13084 | N24: 0.0115 | O24: 575696 | P24: 0.0104 | Q24: 18992 | R24: 205427 | S24: 0.0925 | T24: 9 | U24: 923 | Y24: 7天无理由|蚂蚁花呗|信用卡支付|集分宝|如实描述 | Z24: 广东广州 | AA24: 陈燕芬yyen | AB24: 41568.538 | AC24: 5钻 | AD24: 4.8; 4.7; 4.7 | AE24: 2296 | AF24: 淘宝 | AG24: 0.9596 | AH24: 女装/女士精品 | AI24: 连衣裙 | AK24: 42243 | AL24: 0.45844907 | AM24: 3天16时50分25秒 | AN24: 四 | AO24: http://item.taobao.com/item.htm?id=520826757637 | AP24: http://item.kandianbao.com/520826757637/ | AQ24: 两件套 | AR24: 51%(含)-70%(含) | AT24: 圆领 | AU24: 套头 | AV24: 粉色【两件套】，灰色【两件套】，绿色【两件套】，粉色外套，灰色外套，绿色外套，背心单件 | AW24: 复古 | AX24: S，M，L，XL，2XL，3XL | AY24: 纯色 | AZ24: 长裙 | BA24: 其他/other | BD24: 荷叶边，不对称，纽扣 | BF24: 大摆型 | BG24: 2015年夏季 | BI24: 常规 | BK24: 通勤 | BM24: 宽松腰 | BP24: 25-29周岁 | BQ24: 五分袖 | BR24: 很舒服(31) ; 外形好看(21) ; 衣服不错(16) ; 很划算(14) ; 穿着美(13) ; 码数很准(11) ;
A25: 23 | B25: 第 1 页 第 23 位 | C25: 2015韩版小清新性感露肩收腰碎花连衣裙夏女学生修身显瘦雪纺裙子 | E25: 139 | F25: 0.1727 | G25: 24 | H25: 24 | I25: 152744 | J25: 包邮 | K25: 8296 | L25: 0.0097 | M25: 9094 | N25: 0.008 | O25: 218256 | P25: 0.004 | Q25: 61206 | R25: 88663 | S25: 0.6903 | T25: 2 | U25: 7632 | Y25: 7天无理由|蚂蚁花呗|信用卡支付|集分宝|如实描述 | Z25: 广东广州 | AA25: 小小盼z | AB25: 41568.556 | AC25: 3冠 | AD25: 4.4; 4.5; 4.4 | AE25: 12566 | AF25: 淘宝 | AG25: 0.9443 | AH25: 女装/女士精品 | AI25: 连衣裙 | AK25: 42239 | AL25: 0.91447917 | AM25: 0.15770833 | AN25: 日 | AO25: http://item.taobao.com/item.htm?id=45781507725 | AP25: http://item.kandianbao.com/45781507725/ | AQ25: 单件 | AR25: 31%(含)-50%(含) | AT25: 圆领 | AU25: 其他 | AV25: 白色 优质雪纺，黑色 优质雪纺，白色 普通布料，黑色 普通布料 | AW25: 韩版 | AX25: 收藏送礼，S，M，L，XL，2XL | AY25: 碎花 | AZ25: 中裙 | BA25: 其他/other | BC25: 雪纺 | BD25: 印花 | BG25: 2015年夏季 | BI25: 其他 | BK25: 通勤 | BM25: 松紧腰 | BN25: 其他 | BP25: 18-24周岁 | BQ25: 短袖 | BR25: 版式好(733) ; 整体不错(682) ; 很舒服(472) ; 穿着美(408) ; 尺码很准(183) ; 物流太慢(86) ;
A26: 24 | B26: 第 1 页 第 24 位 | C26: 欧洲站2015新款夏季印花连衣裙欧根纱高腰短裙韩版背心裙女装包邮 | D26: 1005 | E26: 336 | F26: 0.5298 | G26: 178 | H26: 178 | I26: 5433 | J26: 包邮 | K26: 8293 | L26: 0.0097 | M26: 10574 | N26: 0.0093 | O26: 1882172 | P26: 0.0341 | Q26: 154226 | R26: 749378 | S26: 0.2058 | T26: 78 | U26: 2177 | Y26: 卖家承诺48小时内发货|7天无理由|蚂蚁花呗|信用卡支付|集分宝|如实描述 | Z26: 浙江杭州 | AA26: 童年梦之路 | AB26: 41902.902 | AC26: 1冠 | AD26: 4.6; 4.7; 4.6 | AE26: 37061 | AF26: 淘宝 | AG26: 0.9791 | AH26: 女装/女士精品 | AI26: 连衣裙 | AK26: 42244 | AL26: 0.91806713 | AM26: 5天3时52分16秒 | AN26: 五 | AO26: http://item.taobao.com/item.htm?id=520543428983 | AP26: http://item.kandianbao.com/520543428983/ | AQ26: 单件 | AR26: 81%(含)-90%(含) | AS26: A型 | AT26: 娃娃领 | AU26: 套头 | AV26: 【专属女神范】 | AX26: S，M，L，XL，2XL | AY26: 碎花 | AZ26: 短裙 | BA26: 其他/other | BC26: 欧根纱 | BD26: 印花 | BE26: 1005 | BF26: 百褶裙 | BG26: 2015年夏季 | BI26: 其他 | BK26: 甜美 | BL26: 田园 | BM26: 高腰 | BN26: 棉 | BQ26: 无袖 | BR26: 外形好看(29) ; 穿着效果好(25) ; 质量蛮好(24) ; 衣服很舒服(20) ; 服务态度好(18) ; 做工很赞(17) ;
A27: 25 | B27: 第 1 页 第 25 位 | C27: 2015夏装大码女装超长两件套拼接款修身蕾丝中裙子印花雪纺连衣裙 | D27: 2YF001-6658 | E27: 128 | F27: 0.232 | G27: 29.7 | H27: 29.7 | I27: 24279 | J27: 5 | K27: 8239 | L27: 0.0096 | M27: 10091 | N27: 0.0089 | O27: 299702.7 | P27: 0.0054 | Q27: 19022 | R27: - | S27: - | T27: 1 | U27: 3941 | W27: 满3件，享包邮，送3元优惠券 | Z27: 浙江杭州 | AA27: 漫兰飘香旗舰店 | AB27: 41746.487 | AC27: 4冠 | AD27: 4.6; 4.6; 4.8 | AE27: 45399 | AF27: 天猫 | AG27: 1 | AH27: 女装/女士精品 | AI27: 连衣裙 | AK27: 42241 | AL27: 0.86111111 | AM27: 2天2时30分15秒 | AN27: 二 | AO27: http://item.taobao.com/item.htm?id=520518136294 | AP27: http://item.kandianbao.com/520518136294/ | AQ27: 假两件 | AR27: 95%以上 | AS27: A型 | AT27: 圆领 | AU27: 套头 | AV27: 粉色，浅绿色 | AW27: 淑女 | AX27: M，L，XL，XXL | AY27: 碎花 | AZ27: 中裙 | BA27: 其他/other | BB27: 纯电商(只在线上销售) | BC27: 雪纺 | BD27: 荷叶边，抽褶，褶皱，拼接，印花 | BE27: 2YF001-6658 | BF27: 公主裙 | BG27: 2015年夏季 | BH27: 聚酯纤维100% | BI27: 泡泡袖 | BJ27: 漫兰飘香 | BK27: 通勤 | BM27: 中腰 | BN27: 涤纶 | BP27: 25-29周岁 | BQ27: 短袖 | BR27: 宝贝很赞(466) ; 版式好(343) ; 尺码很准(175) ; 穿着漂亮(155) ; 很舒适(148) ; 尺码不对(58) ;
A28: 26 | B28: 第 1 页 第 26 位 | C28: 彩黛妃2015春夏季新款女装性感气质短袖修身显瘦连衣裙韩版L0180 | D28: L0180 | E28: 128 | F28: 0.1547 | G28: 19.8 | H28: 19.8 | I28: 13683 | J28: 包邮 | K28: 7986 | L28: 0.0093 | M28: 10582 | N28: 0.0093 | O28: 209523.6 | P28: 0.0038 | Q28: 29880 | R28: - | S28: - | T28: 7 | U28: 9696 | Z28: 江苏宿迁 | AA28: 彩黛妃旗舰店 | AB28: 41723.451 | AC28: 1金冠 | AD28: 4.6; 4.6; 4.8 | AE28: 308260 | AF28: 天猫 | AG28: 1 | AH28: 女装/女士精品 | AI28: 连衣裙 | AK28: 42243 | AL28: 0.41960648 | AM28: 3天15时54分29秒 | AN28: 四 | AO28: http://item.taobao.com/item.htm?id=45315416266 | AP28: http://item.kandianbao.com/45315416266/ | AQ28: 单件 | AR28: 95%以上 | AT28: 圆领 | AU28: 套头 | AV28: 十字格 | AW28: 韩版 | AX28: S，M，L，XL，XXL | AY28: 其他 | AZ28: 短裙 | BA28: 其他/other | BC28: 针织 | BE28: L0180 | BF28: 其他 | BG28: 2015年夏季 | BH28: 聚酯纤维94.8% 聚氨酯弹性纤维(氨纶)5.2% | BI28: 常规 | BJ28: 彩黛妃 | BK28: 通勤 | BM28: 高腰 | BN28: 涤纶 | BP28: 25-29周岁 | BQ28: 短袖 | BR28: 宝贝很赞(1715) ; 版型好(1021) ; 穿着漂亮(966) ; 尺寸很准(729) ; 很舒适(574) ; 尺码不对(253) ;
A29: 27 | B29: 第 1 页 第 27 位 | C29: 2015夏季新款韩版女装休闲套装连衣裙裤短袖t恤雪纺衫短裙两件套 | E29: 78 | F29: 0.4872 | G29: 38 | H29: 38 | I29: 268870 | J29: 包邮 | K29: 7916 | L29: 0.0092 | M29: 9298 | N29: 0.0082 | O29: 353324 | P29: 0.0064 | Q29: 21184 | R29: 54126 | S29: 0.3914 | T29: 15 | U29: 3152 | Y29: 卖家承诺72小时内发货|7天无理由|蚂蚁花呗|信用卡支付|集分宝|如实描述 | Z29: 广东广州 | AA29: 雅丹娜韩版女装 | AB29: 41586.934 | AC29: 3冠 | AD29: 4.5; 4.5; 4.4 | AE29: 8607 | AF29: 淘宝 | AG29: 0.9494 | AH29: 女装/女士精品 | AI29: 连衣裙 | AK29: 42240 | AL29: 0.44097222 | AM29: 0.68420139 | AN29: 一 | AO29: http://item.taobao.com/item.htm?id=520090687820 | AP29: http://item.kandianbao.com/520090687820/ | AQ29: 两件套 | AR29: 81%(含)-90%(含) | AT29: 圆领 | AU29: 套头 | AV29: 白色短袖上衣，黑色短袖上衣，红色短袖上衣，黑色短裙，红色短裙，短袖白衣+黑裙，短袖白衣+红裙，短袖黑衣+黑裙，短袖黑衣+红裙，短袖红衣+黑裙，短袖红衣+红裙，白色长袖上衣，红色长袖上衣，长袖红衣+黑裙，长袖白衣+黑裙，长袖白衣+红裙，长袖红衣+红裙 | AW29: 韩版 | AX29: S，M，L，XL，2XL | AY29: 纯色 | AZ29: 短裙 | BA29: 其他/other | BC29: 雪纺 | BD29: 蝴蝶结，荷叶边，抽褶，拼接，纽扣 | BF29: 百褶裙 | BG29: 2015年夏季 | BI29: 泡泡袖 | BK29: 通勤 | BM29: 中腰 | BN29: 棉 | BQ29: 短袖 | BR29: 质量好(368) ; 外形好看(297) ; 穿上好看(131) ; 衣衣很舒服(130) ; 码数很准(100) ; 款式蛮好(71) ;
A30: 28 | B30: 第 1 页 第 28 位 | C30: 1嫣洛-dl04新款2015夏装韩版女装圆领时髦女郎印花收腰连衣裙F-29 | E30: 110 | F30: 0.49 | G30: 53.9 | H30: 53.9 | I30: 3457 | J30: 包邮 | K30: 7704 | L30: 0.009 | M30: 8426 | N30: 0.0074 | O30: 454161.4 | P30: 0.0082 | Q30: 73858 | R30: 638129 | S30: 0.1157 | T30: 57 | U30: 11990 | Y30: 7天无理由|集分宝|支付宝支付|如实描述 | Z30: 浙江杭州 | AA30: 日韩女装专卖 | AB30: 39140.893 | AC30: 4金冠 | AD30: 4.6; 4.7; 4.6 | AE30: 4387178 | AF30: 淘宝 | AG30: 0.9879 | AH30: 女装/女士精品 | AI30: 连衣裙 | AK30: 42242 | AL30: 0.41898148 | AM30: 2天15时53分35秒 | AN30: 三 | AO30: http://item.taobao.com/item.htm?id=520232454502 | AP30: http://item.kandianbao.com/520232454502/ | AQ30: 单件 | AR30: 30%及以下 | AT30: 圆领 | AU30: 套头 | AV30: 米白色，蓝色 | AX30: S，M，L，XL | AY30: 人物 | AZ30: 中长裙 | BD30: 系带，印花 | BF30: 其他 | BG30: 2015年夏季 | BI30: 常规 | BK30: 通勤 | BM30: 松紧腰 | BP30: 18-24周岁 | BQ30: 短袖 | BR30: 版型漂亮(1343) ; 宝贝很赞(1252) ; 很舒适(1106) ; 穿着漂亮(894) ; 大小合适(650) ; 面料一般(163) ;
A31: 29 | B31: 第 1 页 第 29 位 | C31: 2015夏季韩国碎花打底吊带裙女装修身背带短裙雪纺收腰显瘦连衣裙 | E31: 43 | F31: 0.4884 | G31: 21 | H31: 21 | I31: 17788 | J31: 包邮 | K31: 7573 | L31: 0.0088 | M31: 8794 | N31: 0.0078 | O31: 184674 | P31: 0.0033 | Q31: 26472 | R31: 28697 | S31: 0.9225 | T31: 7 | U31: 1892 | Y31: 7天无理由|集分宝|支付宝支付|如实描述 | Z31: 广东广州 | AA31: 小晗子家 | AB31: 41733.533 | AC31: 5钻 | AD31: 4.7; 4.7; 4.6 | AE31: 6583 | AF31: 淘宝 | AG31: 0.9777 | AH31: 女装/女士精品 | AI31: 连衣裙 | AK31: 42245 | AL31: 0.63194444 | AM31: 5天21时0分15秒 | AN31: 六 | AO31: http://item.taobao.com/item.htm?id=520063878818 | AP31: http://item.kandianbao.com/520063878818/ | AQ31: 单件 | AR31: 71%(含)-80%(含) | AT31: 圆领 | AU31: 套头 | AV31: 浅黄底花 好质量，黑底花 好质量 | AW31: 韩版 | AX31: M码 质量保证，L码 质量保证，XL码 质量保证，XL码 普通质量 | AY31: 碎花 | AZ31: 短裙 | BA31: 背带 | BC31: 其他 | BD31: 褶皱，拼接 | BF31: 公主裙 | BG31: 2015年夏季 | BI31: 常规 | BK31: 通勤 | BM31: 高腰 | BQ31: 无袖 | BR31: 质量好(140) ; 很舒适(108) ; 版型好(94) ; 穿着漂亮(85) ; 尺寸很准(52) ; 没有色差(34) ;
A32: 30 | B32: 第 1 页 第 30 位 | C32: 中年妈妈装中老年连衣裙35-40-45-50岁大码妇女装短袖花裙子夏装 | D32: 1305 | E32: 128 | F32: 0.1779 | G32: 22.77 | H32: 22.77 | I32: 5070 | J32: 包邮 | K32: 7510 | L32: 0.0088 | M32: 15345 | N32: 0.0135 | O32: 349405.65 | P32: 0.0063 | Q32: 28944 | R32: 482843 | S32: 0.0599 | T32: 620 | U32: 12841 | Y32: 8天退货，退货邮费买家承担|蚂蚁花呗|信用卡支付|集分宝|如实描述 | Z32: 北京 | AA32: 945xujie945 | AB32: 41423.361 | AC32: 3冠 | AD32: 4.7; 4.7; 4.7 | AE32: 5740 | AF32: 淘宝 | AG32: 0.9927 | AH32: 女装/女士精品 | AI32: 连衣裙 | AK32: 42239 | AL32: 0.86365741 | AM32: 0.10688657 | AN32: 日 | AO32: http://item.taobao.com/item.htm?id=38096663728 | AP32: http://item.kandianbao.com/38096663728/ | AQ32: 单件 | AR32: 95%以上 | AS32: A型 | AT32: 其他 | AU32: 套头 | AV32: 03色，05色，08色，09色，10色，11色，12色，13色，15色，16色，18色，25色，29色，26色，19色，27色，28色，21色，20色，22色，23色，17色藏蓝底，宝蓝色，深紫色 | AW32: 民族风 | AX32: 衣服偏小点，拿不准参考尺码表，L，XL，2XL，3XL，4XL | AY32: 花色 | AZ32: 中长裙 | BA32: 其他/other | BC32: 其他 | BD32: 印花 | BE32: 1305 | BF32: 大摆型 | BG32: 2015年夏季 | BI32: 常规 | BJ32: 康之轩 | BK32: 通勤 | BM32: 中腰 | BN32: 其他 | BP32: 40-49周岁 | BQ32: 短袖 | BR32: 宝贝很赞(1543) ; 衣衣很舒服(1438) ; 外形好看(1006) ; 人群(991) ; 穿上好看(672) ; 物流慢(117) ;
A33: 31 | B33: 第 1 页 第 31 位 | C33: 2015夏季新款修身背心裙 欧美竖条纹显瘦无袖连衣裙V领蓬蓬连衣裙 | E33: 111 | F33: 0.2432 | G33: 27 | H33: 27 | I33: 26367 | J33: 包邮 | K33: 7452 | L33: 0.0087 | M33: 7822 | N33: 0.0069 | O33: 211194 | P33: 0.0038 | Q33: 36440 | R33: 73622 | S33: 0.495 | T33: 6 | U33: 4974 | Y33: 卖家承诺72小时内发货|7天无理由|蚂蚁花呗|信用卡支付|集分宝|如实描述 | Z33: 广东广州 | AA33: 潮_流范儿 | AB33: 41738.737 | AC33: 2冠 | AD33: 4.6; 4.6; 4.5 | AE33: 5722 | AF33: 淘宝 | AG33: 0.9699 | AH33: 女装/女士精品 | AI33: 连衣裙 | AK33: 42239 | AL33: 0.92021991 | AM33: 0.16344907 | AN33: 日 | AO33: http://item.taobao.com/item.htm?id=520589940228 | AP33: http://item.kandianbao.com/520589940228/ | AQ33: 单件 | AR33: 51%(含)-70%(含) | AS33: A型 | AT33: V领 | AU33: 套头 | AV33: 图色【优质面料】，【普通粗糙版】 | AX33: S，M，L，XL | AY33: 条纹 | AZ33: 中裙 | BA33: 背带 | BC33: 其他 | BF33: 公主裙 | BG33: 2015年夏季 | BI33: 常规 | BK33: 甜美 | BL33: 学院 | BM33: 中腰 | BN33: 其他 | BP33: 18-24周岁 | BQ33: 无袖 | BR33: 版型好(95) ; 质量不错(87) ; 穿上好看(85) ; 划算(68) ; 衣衣很舒服(67) ; 料子好(36) ;
A34: 32 | B34: 第 1 页 第 32 位 | C34: 2015秋季新款女装大码印花裙子中长款长袖女士t恤时尚连衣裙女秋 | D34: FXYL2313 | E34: 88 | F34: 0.2727 | G34: 24 | H34: 24 | I34: 69092 | J34: 包邮 | K34: 7395 | L34: 0.0086 | M34: 8631 | N34: 0.0076 | O34: 207144 | P34: 0.0037 | Q34: 10296 | R34: - | S34: - | T34: 1 | U34: 2886 | Z34: 浙江杭州 | AA34: famcheyo法香郁旗舰店 | AB34: 41466.552 | AC34: 4冠 | AD34: 4.7; 4.7; 4.7 | AE34: 15369 | AF34: 天猫 | AG34: 1 | AH34: 女装/女士精品 | AI34: 连衣裙 | AK34: 42241 | AL34: 0.78923611 | AM34: 2天46分45秒 | AN34: 二 | AO34: http://item.taobao.com/item.htm?id=520521452563 | AP34: http://item.kandianbao.com/520521452563/ | AQ34: 单件 | AR34: 51%(含)-70%(含) | AT34: 圆领 | AU34: 套头 | AV34: 黑色，白色，灰色 | AW34: 韩版 | AX34: M，L，XL，XXL | AY34: 字母 | AZ34: 中长裙 | BA34: 其他/other | BB34: 纯电商(只在线上销售) | BD34: 蝴蝶结，荷叶边，铆钉，植绒，流苏，破洞，镂空，抽褶，肩章，亮丝，镶钻，露背，油漆喷溅，手工磨破，贴布，绣花，链条，褶皱，木耳，勾花镂空，口袋，系带，拼接，螺纹，扎花，立体装饰，不对称，绑带，扎染，钉珠，波浪，做旧，亮片，背带，纽扣，纱网，拉链，乱针修补，锈斑处理，树脂固色，蕾丝，燕尾，3D，印花 | BE34: FXYL2313 | BF34: A字裙 | BG34: 2015年夏季 | BH34: 新型聚酯纤维65% 其他35% | BI34: 常规 | BJ34: FAMCHEYO/法·香·郁 | BK34: 通勤 | BM34: 中腰 | BN34: 其他 | BP34: 18-24周岁 | BQ34: 长袖 | BR34: 衣服不错(131) ; 衣服很舒服(122) ; 布料好(82) ; 板型很好(44) ; 码子很准(38) ; 穿着效果好(26) ;
A35: 33 | B35: 第 1 页 第 33 位 | C35: 韩国代购2015夏装新款无袖公主连衣裙女宽松大码蓬蓬裙高腰娃娃衫 | D35: 25 | E35: 680 | F35: 0.115 | G35: 78.21 | H35: 78.21 | I35: 8081 | J35: 包邮 | K35: 7393 | L35: 0.0086 | M35: 7936 | N35: 0.007 | O35: 620674.56 | P35: 0.0112 | Q35: 37774 | R35: 57050 | S35: 0.6621 | T35: 5 | U35: 2592 | Y35: 7天无理由|蚂蚁花呗|信用卡支付|集分宝|如实描述 | Z35: 广东广州 | AA35: 魅影mylove | AB35: 41052.815 | AC35: 3冠 | AD35: 4.7; 4.8; 4.7 | AE35: 70278 | AF35: 淘宝 | AG35: 0.9813 | AH35: 女装/女士精品 | AI35: 连衣裙 | AK35: 42244 | AL35: 0.59236111 | AM35: 4天20时3分15秒 | AN35: 五 | AO35: http://item.taobao.com/item.htm?id=520425699980 | AP35: http://item.kandianbao.com/520425699980/ | AQ35: 单件 | AR35: 81%(含)-90%(含) | AS35: A型 | AT35: 圆领 | AU35: 套头 | AV35: 白色，深蓝色 | AW35: 韩版 | AX35: S，M，L，XL，2XL | AY35: 纯色 | AZ35: 短裙 | BA35: 其他/other | BD35: 抽褶，褶皱，系带 | BE35: 25 | BF35: 大摆型 | BG35: 2015年夏季 | BI35: 常规 | BK35: 通勤 | BM35: 高腰 | BN35: 棉 | BP35: 18-24周岁 | BQ35: 无袖 | BR35: 质量好(108) ; 衣衣很舒服(78) ; 外形好看(60) ; 穿上好看(50) ; 款式蛮好(47) ; 做工好(46) ;
A36: 34 | B36: 第 1 页 第 34 位 | C36: 2015韩版大码甜美碎花修身显瘦中裙夏中长款中袖印花雪纺连衣裙秋 | D36: 8858 | E36: 91 | F36: 0.3297 | G36: 30 | H36: 30 | I36: 164161 | J36: 包邮 | K36: 7352 | L36: 0.0086 | M36: 9175 | N36: 0.0081 | O36: 275250 | P36: 0.005 | Q36: 32076 | R36: 72412 | S36: 0.443 | T36: 3 | U36: 3037 | Y36: 卖家承诺48小时内发货|8天退货，退货邮费卖家承担|蚂蚁花呗|信用卡支付|集分宝|如实描述 | Z36: 广东广州 | AA36: 亚洲电商shopping平台 | AB36: 41933.248 | AC36: 2冠 | AD36: 4.7; 4.7; 4.7 | AE36: 5773 | AF36: 淘宝 | AG36: 0.9739 | AH36: 女装/女士精品 | AI36: 连衣裙 | AK36: 42244 | AL36: 0.83333333 | AM36: 5天1时50分15秒 | AN36: 五 | AO36: http://item.taobao.com/item.htm?id=520563537761 | AP36: http://item.kandianbao.com/520563537761/ | AQ36: 单件 | AR36: 71%(含)-80%(含) | AS36: A型 | AT36: 圆领 | AU36: 套头 | AV36: 绿色原图小花，黄色原图小花，粉色原图小花，收藏送运费险，收藏送淘金币 | AW36: 韩版 | AX36: S【优质原版】，M【优质原版】，L【优质原版】，XL【优质原版】，2XL【优质原版】，3XL【优质原版】，S【普通面料】，M【普通面料】，L【普通面料】，XL【普通面料】，2XL【普通面料】，3XL【普通面料】 | AY36: 碎花 | AZ36: 中长裙 | BA36: 其他/other | BC36: 雪纺 | BD36: 蝴蝶结，木耳，印花 | BE36: 8858 | BF36: A字裙 | BG36: 2015年夏季 | BI36: 喇叭袖 | BJ36: 时尚新版女装 | BK36: 通勤 | BM36: 中腰 | BN36: 莫代尔 | BP36: 18-24周岁 | BQ36: 五分袖 | BR36: 质量蛮好(53) ; 版型好(47) ; 很舒服(34) ; 便宜(29) ; 尺寸很准(22) ; 穿着美(19) ;
A37: 35 | B37: 第 1 页 第 35 位 | C37: 欧洲站2015夏季女装印花连衣裙夏中裙时尚显瘦大码胖mm雪纺裙子 | E37: 87 | F37: 0.2947 | G37: 25.64 | H37: 25.64 | I37: 26956 | J37: 包邮 | K37: 7166 | L37: 0.0084 | M37: 7929 | N37: 0.007 | O37: 203299.56 | P37: 0.0037 | Q37: 11134 | R37: 23607 | S37: 0.4716 | T37: 12 | U37: 2142 | Y37: 卖家承诺24小时内发货|7天无理由|集分宝|支付宝支付|如实描述 | Z37: 广东广州 | AA37: 幸福是会重生的 | AB37: 41693.62 | AC37: 2冠 | AD37: 4.7; 4.7; 4.6 | AE37: 4113 | AF37: 淘宝 | AG37: 0.9768 | AH37: 女装/女士精品 | AI37: 连衣裙 | AK37: 42245 | AL37: 0.88935185 | AM37: 6天3时10分55秒 | AN37: 六 | AO37: http://item.taobao.com/item.htm?id=520661672994 | AP37: http://item.kandianbao.com/520661672994/ | AQ37: 单件 | AR37: 81%(含)-90%(含) | AT37: 圆领 | AU37: 套头 | AV37: 黑色 | AX37: S，M，L，XL | AY37: 花色 | AZ37: 短裙 | BA37: 其他/other | BC37: 雪纺 | BD37: 抽褶，拼接，纽扣，蕾丝，印花 | BF37: 其他 | BG37: 2015年夏季 | BI37: 喇叭袖 | BK37: 甜美 | BL37: 公主 | BM37: 松紧腰 | BQ37: 五分袖
A38: 36 | B38: 第 1 页 第 36 位 | C38: 2015夏装新款显瘦牛仔连衣裙背带裙女夏季潮学生牛仔吊带背心短裙 | E38: 140 | F38: 0.15 | G38: 21 | H38: 21 | I38: 413406 | J38: 包邮 | K38: 7121 | L38: 0.0083 | M38: 11486 | N38: 0.0101 | O38: 241206 | P38: 0.0044 | Q38: 7220 | R38: 18854 | S38: 0.3829 | T38: 7 | U38: 561 | Y38: 卖家承诺24小时内发货|8天退货，退货邮费买家承担|蚂蚁花呗|信用卡支付|集分宝|如实描述 | Z38: 广东中山 | AA38: 限量女装批发 | AB38: 40998.901 | AC38: 3钻 | AD38: 4.7; 4.8; 4.7 | AE38: 1942 | AF38: 淘宝 | AG38: 0.9968 | AH38: 女装/女士精品 | AI38: 连衣裙 | AK38: 42239 | AL38: 0.90625 | AM38: 0.14947917 | AN38: 日 | AO38: http://item.taobao.com/item.htm?id=520591170917 | AP38: http://item.kandianbao.com/520591170917/ | AQ38: 单件 | AR38: 81%(含)-90%(含) | AV38: 深蓝色 | AX38: XXS，XS，S，M，L，XL | AY38: 纯色 | AZ38: 短裙 | BA38: 背带 | BC38: 牛仔布 | BD38: 口袋，背带，纽扣 | BF38: 其他 | BG38: 2015年夏季 | BI38: 其他 | BJ38: 无 | BK38: 甜美 | BL38: 学院 | BM38: 宽松腰 | BN38: 醋纤 | BP38: 18-24周岁 | BQ38: 无袖 | BR38: 质量蛮好(138) ; 很舒服(44) ; 穿着美(38) ; 款式很潮(34) ; 衣服很合身(31) ; 版型好看(30) ;
A39: 37 | B39: 第 1 页 第 37 位 | C39: 2015性感荷叶边露肩雪纺连衣裙夏女A字裙短裙宽松显瘦韩国QZ106 | D39: QZ106 | E39: 158 | F39: 0.6203 | G39: 98 | H39: 98 | I39: 15992 | J39: 包邮 | K39: 7053 | L39: 0.0082 | M39: 7537 | N39: 0.0066 | O39: 738626 | P39: 0.0134 | Q39: 147526 | R39: 331485 | S39: 0.445 | T39: 5 | U39: 3959 | Y39: 卖家承诺12天内发货|7天无理由|蚂蚁花呗|信用卡支付|集分宝|如实描述 | Z39: 浙江杭州 | AA39: 女人顶顶大 | AB39: 39248.559 | AC39: 2金冠 | AD39: 4.6; 4.7; 4.7 | AE39: 2664091 | AF39: 淘宝 | AG39: 0.9897 | AH39: 女装/女士精品 | AI39: 连衣裙 | AK39: 42241 | AL39: 0.41666667 | AM39: 1天15时50分15秒 | AN39: 二 | AO39: http://item.taobao.com/item.htm?id=520340311664 | AP39: http://item.kandianbao.com/520340311664/ | AQ39: 单件 | AR39: 31%(含)-50%(含) | AS39: A型 | AT39: V领 | AU39: 套头 | AV39: 白色，粉红色，蓝色 | AW39: 韩版 | AX39: S，M | AY39: 纯色 | AZ39: 短裙 | BC39: 雪纺 | BD39: 荷叶边，镂空 | BE39: QZ106 | BF39: 荷叶边裙 | BG39: 2015年夏季 | BI39: 荷叶袖 | BK39: 通勤 | BM39: 宽松腰 | BP39: 18-24周岁 | BQ39: 短袖 | BR39: 版型漂亮(97) ; 质量好(84) ; 穿上好看(36) ; 衣衣很舒服(30) ; 色彩很好(29) ; 和描述一致(19) ;
A40: 38 | B40: 第 1 页 第 38 位 | C40: 韩国代购2015夏装新款女装明星同款修身A字裙中裙红色连衣裙夏季 | E40: 193 | F40: 0.1554 | G40: 30 | H40: 30 | I40: 11042 | J40: 包邮 | K40: 6974 | L40: 0.0081 | M40: 8895 | N40: 0.0078 | O40: 266850 | P40: 0.0048 | Q40: 39956 | R40: 116581 | S40: 0.3427 | T40: 7 | U40: 8214 | Y40: 卖家承诺24小时内发货|7天无理由|蚂蚁花呗|集分宝|支付宝支付|如实描述 | Z40: 广东广州 | AA40: hao87882894 | AB40: 41500.954 | AC40: 2冠 | AD40: 4.6; 4.6; 4.5 | AE40: 3240 | AF40: 淘宝 | AG40: 0.9598 | AH40: 女装/女士精品 | AI40: 连衣裙 | AK40: 42244 | AL40: 0.88888889 | AM40: 5天3时10分15秒 | AN40: 五 | AO40: http://item.taobao.com/item.htm?id=45355935820 | AP40: http://item.kandianbao.com/45355935820/ | AQ40: 单件 | AR40: 81%(含)-90%(含) | AT40: 圆领 | AU40: 套头 | AV40: 白色，红色 | AW40: 韩版 | AX40: S【优质面料】，M【优质面料】，L【优质面料】，XL【优质面料】，S【普通面料】，M【普通面料】，L【普通面料】，XL【普通面料】 | AY40: 纯色 | AZ40: 中长裙 | BA40: 其他/other | BC40: 针织 | BD40: 荷叶边 | BF40: 公主裙 | BG40: 2015年夏季 | BI40: 常规 | BK40: 通勤 | BM40: 中腰 | BQ40: 短袖 | BR40: 版型好看(1137) ; 宝贝很赞(996) ; 穿上好看(882) ; 色彩很好(418) ; 衣衣很舒服(386) ; 颜色不行(222) ;
...

Sheet Sheet3
B2: 单元格 | C2: BD列（地区） | E2: =源数据!U132 -> 杭州的商品 | F2: =源数据!V132 -> 39
B3: BD1 | C3: 浙江杭州 | E3: =源数据!U133 -> 短裙数量 | F3: =源数据!V133 -> 47
B4: BD2 | C4: 广东广州 | E4: =源数据!U134 -> 广州的短裙数量 | F4: =源数据!V134 -> 29
B5: BD3 | C5: 广东东莞 | E5: =源数据!U135 -> 通勤风数量 | F5: =源数据!V135 -> 94
B6: BD4 | C6: 广东中山 | E6: =源数据!U138 -> 杭州的30天总销售额 | F6: =源数据!V138 -> 28947488
B7: BD5 | C7: 江苏宿迁 | E7: =源数据!U139 -> 广州短裙的30天总销售额 | F7: =源数据!V139 -> 8743432.1
B8: BD6 | C8: 北京 | E8: =源数据!U140 -> 店铺信誉是"5冠"的30天总销量 | F8: =源数据!V140 -> 71321
B9: BD7 | C9: 山东青岛 | E9: =源数据!U141 -> 风格是"甜美"的总收藏量 | F9: =源数据!V141 -> 1797767
B10: BD8 | C10: 江苏苏州 | E10: =源数据!U142 -> 长裙的平均销售价 | F10: =源数据!V142 -> 52.444583
B11: BD9 | C11: 广东深圳
B12: BD10 | C12: 广东揭阳
B13: BD11 | C13: 江苏徐州
B16: BD列（信誉） | C16: BE列（等级描述） | F16: =源数据!AJ130 -> 头部卖家-顶
B17: 3钻 | C17: 老店-中等 | F17: =源数据!AJ131 -> #N/A
B18: 4钻 | C18: 老店-中上 | F18: =源数据!AJ132 -> #N/A
B19: 5钻 | C19: 老店-较高 | F19: =源数据!AJ133 -> #N/A
B20: 1冠 | C20: 成熟店-入门 | F20: =源数据!AJ134 -> #N/A
B21: 2冠 | C21: 成熟店-标准 | F21: =源数据!AJ135 -> #N/A
B22: 3冠 | C22: 成熟店-较强 | F22: =源数据!AJ136 -> 头部卖家-高
B23: 4冠 | C23: 成熟店-头部 | F23: =源数据!AJ137 -> 头部卖家-高
B24: 5冠 | C24: 成熟店-顶级 | F24: =源数据!AJ138 -> 成熟店-较强
B25: 1金冠 | C25: 头部卖家-初 | F25: =源数据!AJ139 -> 头部卖家-顶
B26: 2金冠 | C26: 头部卖家-中 | F26: =源数据!AJ140 -> #N/A
B27: 3金冠 | C27: 头部卖家-高 | F27: =源数据!AJ141 -> 头部卖家-高
B28: 4金冠 | C28: 头部卖家-顶 | F28: =源数据!AJ142 -> #N/A
F29: =源数据!AJ143 -> 头部卖家-高
F30: =源数据!AJ144 -> #N/A
F31: =源数据!AJ145 -> #N/A
F32: =源数据!AJ146 -> 成熟店-较强
F33: =源数据!AJ147 -> 成熟店-较强
F34: =源数据!AJ148 -> 成熟店-较强

Sheet 处理后的数据
A1: 序号 | B1: 排名位置 | C1: 宝贝名称：看店宝【kandianbao.com】 | D1: 货号 | E1: 原价 | F1: 折扣率 | G1: 销售价 | H1: 手机价 | I1: 库存 | J1: 邮费 | K1: 30天收货 | L1: 收货占比 | M1: 30天销量 | N1: 销量占比 | O1: 30天销售额 | P1: 销售额占比 | Q1: 总收藏量 | R1: PC总浏览量 | S1: 收藏比 | T1: 总分享数 | U1: 总评价数 | V1: 宝贝促销 | W1: 店铺促销 | X1: 活动促销 | Y1: 服务保证 | Z1: 所在地 | AA1: 店铺掌柜 | AB1: 开店日期 | AC1: 店铺信誉 | AD1: 店铺dsr | AE1: 店铺收藏 | AF1: 店铺类型 | AG1: 好评率 | AH1: 一级类目 | AI1: 二级类目 | AJ1: 三级类目 | AK1: 下架日期 | AL1: 下架时间 | AM1: 天数 | AN1: 星期 | AO1: 小时 | AP1: 宝贝地址
A2: 1 | B2: 第 1 页 第 1 位 | C2: 2015夏季新款韩版通勤女装圆领短袖气质修身ol连衣裙女中裙淑女裙 | E2: 468 | F2: 0.3342 | G2: 156.42 | H2: 156.42 | I2: 8011 | J2: 包邮 | K2: 21808 | L2: 0.0255 | M2: 30590 | N2: 0.027 | O2: 4784887.8 | P2: 0.0866 | Q2: 173404 | R2: 649367 | S2: 0.267 | T2: 21 | U2: 3096 | Y2: 8天退货，退货邮费买家承担|蚂蚁花呗|信用卡支付|集分宝|如实描述 | Z2: 浙江杭州 | AA2: 悠然1149 | AB2: 41953.842 | AC2: 2冠 | AD2: 4.8; 4.8; 4.8 | AE2: 36209 | AF2: 淘宝 | AG2: 0.9846 | AH2: 女装/女士精品 | AI2: 连衣裙 | AK2: 42240 | AL2: 0.92013889 | AM2: 1天3时55分15秒 | AN2: 一 | AO2: =HOUR(AL2) -> 22 | AP2: http://item.taobao.com/item.htm?id=520635131814
A3: 2 | B3: 第 1 页 第 2 位 | C3: 夏季连衣裙大码女装背心裙中长款包臀长裙内搭打底衫OL修身吊带裙 | D3: 6013- | E3: 104 | F3: 0.1827 | G3: 19 | H3: 19 | I3: 65359 | J3: 包邮 | K3: 21031 | L3: 0.0246 | M3: 35057 | N3: 0.0309 | O3: 666083 | P3: 0.0121 | Q3: 48530 | R3: 60393 | S3: 0.8036 | T3: 9 | U3: 3435 | Y3: 7天无理由|蚂蚁花呗|信用卡支付|集分宝|如实描述 | Z3: 广东东莞 | AA3: 物美价廉yy8 | AB3: 41705.55 | AC3: 1冠 | AD3: 4.6; 4.6; 4.5 | AE3: 2754 | AF3: 淘宝 | AG3: 0.9817 | AH3: 女装/女士精品 | AI3: 连衣裙 | AK3: 42244 | AL3: 0.63888889 | AM3: 4天21时10分15秒 | AN3: 五 | AO3: =HOUR(AL3) -> 15 | AP3: http://item.taobao.com/item.htm?id=45418797934
A4: 3 | B4: 第 1 页 第 3 位 | C4: 2015夏天新款显瘦牛仔背带裙连衣裙女装夏季潮学生牛仔背心短裙子 | E4: 192 | F4: 0.1198 | G4: 23 | H4: 23 | I4: 945466 | J4: 包邮 | K4: 20824 | L4: 0.0243 | M4: 25429 | N4: 0.0224 | O4: 584867 | P4: 0.0106 | Q4: 85198 | R4: 199658 | S4: 0.4267 | T4: 19 | U4: 15799 | Y4: 卖家承诺72小时内发货|8天退货，退货邮费买家承担|蚂蚁花呗|信用卡支付|集分宝|如实描述 | Z4: 广东中山 | AA4: 韩国专柜女装 | AB4: 41681.994 | AC4: 2冠 | AD4: 4.6; 4.6; 4.5 | AE4: 4594 | AF4: 淘宝 | AG4: 0.9637 | AH4: 女装/女士精品 | AI4: 连衣裙 | AK4: 42242 | AL4: 0.90228009 | AM4: 3天3时29分32秒 | AN4: 三 | AO4: =HOUR(AL4) -> 21 | AP4: http://item.taobao.com/item.htm?id=45428232575
A5: 4 | B5: 第 1 页 第 4 位 | C5: 彩黛妃2015新款春夏季大码女装性感修身短袖镂空衣领连衣裙韩版潮 | D5: C0070 | E5: 128 | F5: 0.1547 | G5: 19.8 | H5: 19.8 | I5: 733657 | J5: 包邮 | K5: 17668 | L5: 0.0206 | M5: 22725 | N5: 0.02 | O5: 449955 | P5: 0.0081 | Q5: 105162 | R5: - | S5: - | T5: 179 | U5: 38269 | Z5: 江苏宿迁 | AA5: 彩黛妃旗舰店 | AB5: 41723.451 | AC5: 1金冠 | AD5: 4.6; 4.6; 4.8 | AE5: 308260 | AF5: 天猫 | AG5: 1 | AH5: 女装/女士精品 | AI5: 连衣裙 | AK5: 42245 | AL5: 0.42803241 | AM5: 5天16时6分37秒 | AN5: 六 | AO5: =HOUR(AL5) -> 10 | AP5: http://item.taobao.com/item.htm?id=43944007169
A6: 5 | B6: 第 1 页 第 5 位 | C6: 凤凤服饰2015夏装新款连衣裙夏裙纯色韩版宽松无袖显瘦遮住小肚腩 | D6: 99 | E6: 299 | F6: 0.099 | G6: 29.6 | H6: 29.6 | I6: 20259 | J6: 包邮 | K6: 17586 | L6: 0.0205 | M6: 18265 | N6: 0.0161 | O6: 540644 | P6: 0.0098 | Q6: 26748 | R6: 87202 | S6: 0.3067 | T6: 2 | U6: 6214 | Y6: 7天无理由|蚂蚁花呗|信用卡支付|集分宝|如实描述 | Z6: 广东广州 | AA6: ff2012888 | AB6: 40990.534 | AC6: 2冠 | AD6: 4.0; 4.1; 4.0 | AE6: 3680 | AF6: 淘宝 | AG6: 0.8931 | AH6: 女装/女士精品 | AI6: 连衣裙 | AK6: 42243 | AL6: 0.96678241 | AM6: 4天5时2分25秒 | AN6: 四 | AO6: =HOUR(AL6) -> 23 | AP6: http://item.taobao.com/item.htm?id=520565996333
A7: 6 | B7: 第 1 页 第 6 位 | C7: 2015夏装新款中老年女装印花连衣裙夏季大码修身中年妈妈装碎花裙 | D7: 136 | E7: 88 | F7: 0.1789 | G7: 15.74 | H7: 15.74 | I7: 5830 | J7: 包邮 | K7: 16114 | L7: 0.0188 | M7: 31284 | N7: 0.0276 | O7: 492410.16 | P7: 0.0089 | Q7: 35684 | R7: 763048 | S7: 0.0468 | T7: 277 | U7: 25728 | Y7: 卖家承诺72小时内发货|7天无理由|蚂蚁花呗|信用卡支付|集分宝|如实描述 | Z7: 北京 | AA7: 酷奇宝贝stb | AB7: 40423.859 | AC7: 4冠 | AD7: 4.7; 4.7; 4.7 | AE7: 13776 | AF7: 淘宝 | AG7: 0.9734 | AH7: 女装/女士精品 | AI7: 连衣裙 | AK7: 42239 | AL7: 0.9153588 | AM7: 0.15858796 | AN7: 日 | AO7: =HOUR(AL7) -> 21 | AP7: http://item.taobao.com/item.htm?id=24393792120
A8: 7 | B8: 第 1 页 第 7 位 | C8: 韩国2015春夏季新款女装高腰两件套连衣裙 夏装蓬蓬a字裙短袖套装 | E8: 109 | F8: 0.2661 | G8: 29 | H8: 29 | I8: 1470592 | J8: 包邮 | K8: 14988 | L8: 0.0175 | M8: 25069 | N8: 0.0221 | O8: 727001 | P8: 0.0132 | Q8: 62724 | R8: 55138 | S8: 1.1376 | T8: 2 | U8: 770 | Y8: 卖家承诺20小时内发货|7天无理由|集分宝|支付宝支付|如实描述 | Z8: 广东广州 | AA8: 人生朱1448200051 | AB8: 42183.855 | AC8: 3钻 | AD8: 4.4; 4.4; 4.2 | AE8: 8594 | AF8: 淘宝 | AG8: 0.9627 | AH8: 女装/女士精品 | AI8: 连衣裙 | AK8: 42239 | AL8: 0.88596065 | AM8: 0.12918981 | AN8: 日 | AO8: =HOUR(AL8) -> 21 | AP8: http://item.taobao.com/item.htm?id=520347387757
A9: 8 | B9: 第 1 页 第 8 位 | C9: 2015夏季新品女装 韩版可爱卡通米奇印花开叉中长款短袖T恤连衣裙 | E9: 89 | F9: 0.2022 | G9: 18 | H9: 18 | I9: 2489091 | J9: 包邮 | K9: 13841 | L9: 0.0162 | M9: 18282 | N9: 0.0161 | O9: 329076 | P9: 0.006 | Q9: 38864 | R9: 29307 | S9: 1.3261 | T9: 2 | U9: 5834 | Y9: 7天无理由|蚂蚁花呗|信用卡支付|集分宝|如实描述 | Z9: 广东广州 | AA9: 韩衣馆shop | AB9: 41571.557 | AC9: 3冠 | AD9: 4.7; 4.7; 4.7 | AE9: 10680 | AF9: 淘宝 | AG9: 0.9749 | AH9: 女装/女士精品 | AI9: 连衣裙 | AK9: 42240 | AL9: 0.65258102 | AM9: 0.89581019 | AN9: 一 | AO9: =HOUR(AL9) -> 15 | AP9: http://item.taobao.com/item.htm?id=520221451671
A10: 9 | B10: 第 1 页 第 9 位 | C10: 2015夏装新款套装甜美两件套女装裙子 欧洲站夏季短裙雪纺连衣裙 | E10: 118 | F10: 0.322 | G10: 38 | H10: 38 | I10: 12720 | J10: 包邮 | K10: 12729 | L10: 0.0149 | M10: 14498 | N10: 0.0128 | O10: 550924 | P10: 0.01 | Q10: 111246 | R10: 654964 | S10: 0.1699 | T10: 68 | U10: 15242 | Y10: 卖家承诺72小时内发货|8天退货，退货邮费买家承担|蚂蚁花呗|信用卡支付|集分宝|如实描述 | Z10: 广东广州 | AA10: wanwalkerman | AB10: 41112.482 | AC10: 5冠 | AD10: 4.7; 4.7; 4.6 | AE10: 139674 | AF10: 淘宝 | AG10: 0.9849 | AH10: 女装/女士精品 | AI10: 连衣裙 | AK10: 42239 | AL10: 0.95984954 | AM10: 0.2030787 | AN10: 日 | AO10: =HOUR(AL10) -> 23 | AP10: http://item.taobao.com/item.htm?id=45756314177
A11: 10 | B11: 第 1 页 第 10 位 | C11: 2015夏装新款韩版连衣裙背心裙修身高腰条纹小香风打底裙蓬蓬裙潮 | D11: 0 | E11: 64 | F11: 0.3594 | G11: 23 | H11: 23 | I11: 1554 | J11: 包邮 | K11: 12668 | L11: 0.0148 | M11: 15400 | N11: 0.0136 | O11: 354200 | P11: 0.0064 | Q11: 41830 | R11: 104826 | S11: 0.399 | T11: 5 | U11: 2857 | Y11: 8天退货，退货邮费买家承担|蚂蚁花呗|信用卡支付|集分宝|如实描述 | Z11: 广东广州 | AA11: 美丽呼吸韩版女装 | AB11: 41945.814 | AC11: 1冠 | AD11: 4.7; 4.7; 4.6 | AE11: 3932 | AF11: 淘宝 | AG11: 0.9802 | AH11: 女装/女士精品 | AI11: 连衣裙 | AK11: 42241 | AL11: 0.9172338 | AM11: 2天3时51分4秒 | AN11: 二 | AO11: =HOUR(AL11) -> 22 | AP11: http://item.taobao.com/item.htm?id=520487212484
A12: 11 | B12: 第 1 页 第 11 位 | C12: 2015新雪纺连衣裙大码女装夏装淑女超长款裙子显瘦气质连衣长裙夏 | D12: QDY15B4018 | E12: 103 | F12: 0.5631 | G12: 58 | H12: 58 | I12: 4545 | J12: 包邮 | K12: 11097 | L12: 0.013 | M12: 13899 | N12: 0.0123 | O12: 806142 | P12: 0.0146 | Q12: 71664 | R12: - | S12: - | T12: 20 | U12: 18384 | Z12: 广东广州 | AA12: 迪悠旗舰店 | AB12: 41478.726 | AC12: 4冠 | AD12: 4.8; 4.8; 4.8 | AE12: 51366 | AF12: 天猫 | AG12: 1 | AH12: 女装/女士精品 | AI12: 连衣裙 | AK12: 42242 | AL12: 0.72231481 | AM12: 2天23时10分23秒 | AN12: 三 | AO12: =HOUR(AL12) -> 17 | AP12: http://item.taobao.com/item.htm?id=45728286943
A13: 12 | B13: 第 1 页 第 12 位 | C13: 韩国代购2015夏季新款女装纯棉麻短袖衬衫裙中长款甜美连衣裙子 | D13: WQ057 | E13: 428 | F13: 0.0751 | G13: 32.14 | H13: 32.14 | I13: 10597 | J13: 包邮 | K13: 10980 | L13: 0.0128 | M13: 11642 | N13: 0.0103 | O13: 374173.88 | P13: 0.0068 | Q13: 49080 | R13: 58539 | S13: 0.8384 | T13: 3 | U13: 4712 | Y13: 7天无理由|蚂蚁花呗|信用卡支付|集分宝|如实描述 | Z13: 浙江杭州 | AA13: 普拉达8606 | AB13: 40356.066 | AC13: 1冠 | AD13: 4.7; 4.7; 4.6 | AE13: 2128 | AF13: 淘宝 | AG13: 0.948 | AH13: 女装/女士精品 | AI13: 连衣裙 | AK13: 42241 | AL13: 0.87515046 | AM13: 2天2时50分28秒 | AN13: 二 | AO13: =HOUR(AL13) -> 21 | AP13: http://item.taobao.com/item.htm?id=520178820639
A14: 13 | B14: 第 1 页 第 13 位 | C14: 2015夏装女装长裙子夏季中长款拼接修身大码优雅印花雪纺连衣裙女 | D14: 2YF001-1213 | E14: 498 | F14: 0.0596 | G14: 29.7 | H14: 29.7 | I14: 102289 | J14: 5 | K14: 10964 | L14: 0.0128 | M14: 14074 | N14: 0.0124 | O14: 417997.8 | P14: 0.0076 | Q14: 54144 | R14: - | S14: - | T14: 10 | U14: 10971 | W14: 满3件，享包邮，送3元优惠券 | Z14: 浙江杭州 | AA14: 漫兰飘香旗舰店 | AB14: 41746.487 | AC14: 4冠 | AD14: 4.6; 4.6; 4.8 | AE14: 45399 | AF14: 天猫 | AG14: 1 | AH14: 女装/女士精品 | AI14: 连衣裙 | AK14: 42244 | AL14: 0.66400463 | AM14: 4天21时46分25秒 | AN14: 五 | AO14: =HOUR(AL14) -> 15 | AP14: http://item.taobao.com/item.htm?id=45622403217
A15: 14 | B15: 第 1 页 第 14 位 | C15: 棉麻连衣裙女2015夏季韩版学生小清新短袖中裙女文艺范亚麻裙子潮 | E15: 138 | F15: 0.2246 | G15: 31 | H15: 31 | I15: 50031 | J15: 包邮 | K15: 10740 | L15: 0.0125 | M15: 12348 | N15: 0.0109 | O15: 382788 | P15: 0.0069 | Q15: 60956 | R15: 119568 | S15: 0.5098 | T15: 7 | U15: 6754 | Y15: 10天退货，退货邮费买家承担|蚂蚁花呗|信用卡支付|集分宝|如实描述 | Z15: 浙江杭州 | AA15: 潮流女装62 | AB15: 41300.351 | AC15: 2冠 | AD15: 4.6; 4.7; 4.6 | AE15: 6812 | AF15: 淘宝 | AG15: 0.9722 | AH15: 女装/女士精品 | AI15: 连衣裙 | AK15: 42240 | AL15: 0.875 | AM15: 1天2时50分15秒 | AN15: 一 | AO15: =HOUR(AL15) -> 21 | AP15: http://item.taobao.com/item.htm?id=520101954838
A16: 15 | B16: 第 1 页 第 15 位 | C16: jto 新款印花雪纺连衣裙夏喇叭袖松紧收腰显瘦短裙a字裙女062325 | E16: 87 | F16: 0.8 | G16: 69.6 | H16: 69.6 | I16: 1530 | J16: 包邮 | K16: 10634 | L16: 0.0124 | M16: 11950 | N16: 0.0105 | O16: 831720 | P16: 0.0151 | Q16: 120364 | R16: 252509 | S16: 0.4767 | T16: 4 | U16: 9848 | W16: 1.单笔订单满199元免运费(不包邮地区：内蒙古;黑龙江;甘肃;青海;新疆;西藏;台湾;香港;澳门;海外)，亲，快下手吧！ | Y16: 卖家承诺10天内发货|7天无理由|蚂蚁花呗|信用卡支付|集分宝|如实描述 | Z16: 浙江杭州 | AA16: zjforeverxxxx | AB16: 39643.925 | AC16: 2金冠 | AD16: 4.6; 4.7; 4.7 | AE16: 1458842 | AF16: 淘宝 | AG16: 0.9882 | AH16: 女装/女士精品 | AI16: 连衣裙 | AK16: 42239 | AL16: 0.92184028 | AM16: 0.16506944 | AN16: 日 | AO16: =HOUR(AL16) -> 22 | AP16: http://item.taobao.com/item.htm?id=520200646708
A17: 16 | B17: 第 1 页 第 16 位 | C17: 2015夏季新款小香风条纹胖MM背心连衣裙宽松大码蓬蓬裙高腰娃娃衫 | E17: 262 | F17: 0.0916 | G17: 24 | H17: 24 | I17: 457803 | J17: 包邮 | K17: 10333 | L17: 0.0121 | M17: 11330 | N17: 0.01 | O17: 271920 | P17: 0.0049 | Q17: 66934 | R17: 44914 | S17: 1.4903 | T17: 3 | U17: 2226 | Y17: 7天无理由|蚂蚁花呗|信用卡支付|集分宝|如实描述 | Z17: 广东广州 | AA17: 小小盼z | AB17: 41568.556 | AC17: 3冠 | AD17: 4.4; 4.5; 4.4 | AE17: 12566 | AF17: 淘宝 | AG17: 0.9443 | AH17: 女装/女士精品 | AI17: 连衣裙 | AK17: 42245 | AL17: 0.9190162 | AM17: 6天3时53分38秒 | AN17: 六 | AO17: =HOUR(AL17) -> 22 | AP17: http://item.taobao.com/item.htm?id=520448498247
A18: 17 | B18: 第 1 页 第 17 位 | C18: 2015韩系小清新套装连衣裙女春夏白领拼接两件套装裙吊带背心裙潮 | D18: fashion326 | E18: 127 | F18: 0.2126 | G18: 27 | H18: 27 | I18: 185972 | J18: 包邮 | K18: 10281 | L18: 0.012 | M18: 12390 | N18: 0.0109 | O18: 334530 | P18: 0.0061 | Q18: 85032 | R18: 77105 | S18: 1.1028 | T18: 9 | U18: 5282 | W18: 1.单笔订单满10元免运费(不包邮地区：台湾;香港;澳门;海外)，亲，快下手吧！|2.单笔订单满88元减4元；减后满88元，免运费(不包邮地区：台湾;香港;澳门;海外)，亲，快下手吧！|3.单笔订单满168元减8元；减后满168元，免运费(不包邮地区：台湾;香港;澳门;海外)，亲，快下手吧！|4.单笔订单满328元减16元；减后满328元，免运费(不包邮地区：台湾;香港;澳门;海外)，亲，快下手吧！|5.单笔订单满528元减20元；减后满528元，免运费(不包邮地区：台湾;香港;澳门;海外)，亲，快下手吧！ | Y18: 8天退货，退货邮费买家承担|蚂蚁花呗|信用卡支付|集分宝|如实描述 | Z18: 浙江杭州 | AA18: fashion时尚依馆 | AB18: 41620.015 | AC18: 3冠 | AD18: 4.6; 4.7; 4.6 | AE18: 31264 | AF18: 淘宝 | AG18: 0.9858 | AH18: 女装/女士精品 | AI18: 连衣裙 | AK18: 42245 | AL18: 0.875 | AM18: 6天2时50分15秒 | AN18: 六 | AO18: =HOUR(AL18) -> 21 | AP18: http://item.taobao.com/item.htm?id=45449529737
A19: 18 | B19: 第 1 页 第 18 位 | C19: 2015夏季包臀莫代尔长裙连衣裙大码吊带修身打底背心裙长款长裙 | E19: 89 | F19: 0.3247 | G19: 28.9 | H19: 28.9 | I19: 173717 | J19: 包邮 | K19: 10127 | L19: 0.0118 | M19: 13577 | N19: 0.012 | O19: 392375.3 | P19: 0.0071 | Q19: 29294 | R19: 57926 | S19: 0.5057 | T19: 9 | U19: 4994 | Y19: 卖家承诺72小时内发货|7天无理由|蚂蚁花呗|信用卡支付|集分宝|如实描述 | Z19: 浙江杭州 | AA19: 名款城 | AB19: 40771.765 | AC19: 3冠 | AD19: 4.8; 4.8; 4.7 | AE19: 12999 | AF19: 淘宝 | AG19: 0.9874 | AH19: 女装/女士精品 | AI19: 连衣裙 | AK19: 42241 | AL19: 0.67261574 | AM19: 1天21时58分49秒 | AN19: 二 | AO19: =HOUR(AL19) -> 16 | AP19: http://item.taobao.com/item.htm?id=520135988843
A20: 19 | B20: 第 1 页 第 19 位 | C20: 两件套连衣裙欧洲站2015夏装新款套装雪纺裙子背心休闲短裙气质潮 | E20: 128 | F20: 0.2891 | G20: 37 | H20: 37 | I20: 680 | J20: 包邮 | K20: 8894 | L20: 0.0104 | M20: 12223 | N20: 0.0108 | O20: 452251 | P20: 0.0082 | Q20: 43082 | R20: 78608 | S20: 0.5481 | T20: 2 | U20: 1137 | Y20: 卖家承诺72小时内发货|8天退货，退货邮费买家承担|蚂蚁花呗|信用卡支付|集分宝|如实描述 | Z20: 广东广州 | AA20: 随心良品 | AB20: 41426.388 | AC20: 4冠 | AD20: 4.8; 4.8; 4.8 | AE20: 23117 | AF20: 淘宝 | AG20: 0.9846 | AH20: 女装/女士精品 | AI20: 连衣裙 | AK20: 42242 | AL20: 0.9587963 | AM20: 3天4时50分55秒 | AN20: 三 | AO20: =HOUR(AL20) -> 23 | AP20: http://item.taobao.com/item.htm?id=520523704111
A21: 20 | B21: 第 1 页 第 20 位 | C21: 欧洲站2015夏装新款真丝雪纺水墨印花连衣裙收腰显瘦女裙子欧货 | D21: MY008 | E21: 988 | F21: 0.1615 | G21: 159.6 | H21: 159.6 | I21: 651 | J21: 包邮 | K21: 8733 | L21: 0.0102 | M21: 9760 | N21: 0.0086 | O21: 1557696 | P21: 0.0282 | Q21: 73194 | R21: 690856 | S21: 0.1059 | T21: 22 | U21: 5051 | Y21: 卖家承诺30天内发货|7天无理由|蚂蚁花呗|信用卡支付|集分宝|如实描述 | Z21: 浙江杭州 | AA21: zywj16叶伟林 | AB21: 39874.802 | AC21: 3冠 | AD21: 4.7; 4.8; 4.7 | AE21: 55049 | AF21: 淘宝 | AG21: 0.9758 | AH21: 女装/女士精品 | AI21: 连衣裙 | AK21: 42242 | AL21: 0.84722222 | AM21: 3天2时10分15秒 | AN21: 三 | AO21: =HOUR(AL21) -> 20 | AP21: http://item.taobao.com/item.htm?id=520386051081
A22: 21 | B22: 第 1 页 第 21 位 | C22: 歌兔雪纺连衣裙夏季长裙2015夏装清仓特价修身显瘦中长款女装裙子 | D22: GT15CQZ69 | E22: 298 | F22: 0.2983 | G22: 88.9 | H22: 88.9 | I22: 8437 | J22: 包邮 | K22: 8355 | L22: 0.0098 | M22: 11294 | N22: 0.01 | O22: 1004036.6 | P22: 0.0182 | Q22: 145106 | R22: - | S22: - | T22: 130 | U22: 30222 | Z22: 浙江杭州 | AA22: 歌兔服饰旗舰店 | AB22: 41592.604 | AC22: 5冠 | AD22: 4.8; 4.8; 4.8 | AE22: 105194 | AF22: 天猫 | AG22: 1 | AH22: 女装/女士精品 | AI22: 连衣裙 | AK22: 42240 | AL22: 0.87575231 | AM22: 1天2时51分20秒 | AN22: 一 | AO22: =HOUR(AL22) -> 21 | AP22: http://item.taobao.com/item.htm?id=44548937074
A23: 22 | B23: 第 1 页 第 22 位 | C23: 2015夏季新款气质大码中裙文艺复古棉麻两件套连衣裙亚麻套装裙女 | E23: 144 | F23: 0.3056 | G23: 44 | H23: 44 | I23: 30212 | J23: 包邮 | K23: 8328 | L23: 0.0097 | M23: 13084 | N23: 0.0115 | O23: 575696 | P23: 0.0104 | Q23: 18992 | R23: 205427 | S23: 0.0925 | T23: 9 | U23: 923 | Y23: 7天无理由|蚂蚁花呗|信用卡支付|集分宝|如实描述 | Z23: 广东广州 | AA23: 陈燕芬yyen | AB23: 41568.538 | AC23: 5钻 | AD23: 4.8; 4.7; 4.7 | AE23: 2296 | AF23: 淘宝 | AG23: 0.9596 | AH23: 女装/女士精品 | AI23: 连衣裙 | AK23: 42243 | AL23: 0.45844907 | AM23: 3天16时50分25秒 | AN23: 四 | AO23: =HOUR(AL23) -> 11 | AP23: http://item.taobao.com/item.htm?id=520826757637
A24: 23 | B24: 第 1 页 第 23 位 | C24: 2015韩版小清新性感露肩收腰碎花连衣裙夏女学生修身显瘦雪纺裙子 | E24: 139 | F24: 0.1727 | G24: 24 | H24: 24 | I24: 152744 | J24: 包邮 | K24: 8296 | L24: 0.0097 | M24: 9094 | N24: 0.008 | O24: 218256 | P24: 0.004 | Q24: 61206 | R24: 88663 | S24: 0.6903 | T24: 2 | U24: 7632 | Y24: 7天无理由|蚂蚁花呗|信用卡支付|集分宝|如实描述 | Z24: 广东广州 | AA24: 小小盼z | AB24: 41568.556 | AC24: 3冠 | AD24: 4.4; 4.5; 4.4 | AE24: 12566 | AF24: 淘宝 | AG24: 0.9443 | AH24: 女装/女士精品 | AI24: 连衣裙 | AK24: 42239 | AL24: 0.91447917 | AM24: 0.15770833 | AN24: 日 | AO24: =HOUR(AL24) -> 21 | AP24: http://item.taobao.com/item.htm?id=45781507725
A25: 24 | B25: 第 1 页 第 24 位 | C25: 欧洲站2015新款夏季印花连衣裙欧根纱高腰短裙韩版背心裙女装包邮 | D25: 1005 | E25: 336 | F25: 0.5298 | G25: 178 | H25: 178 | I25: 5433 | J25: 包邮 | K25: 8293 | L25: 0.0097 | M25: 10574 | N25: 0.0093 | O25: 1882172 | P25: 0.0341 | Q25: 154226 | R25: 749378 | S25: 0.2058 | T25: 78 | U25: 2177 | Y25: 卖家承诺48小时内发货|7天无理由|蚂蚁花呗|信用卡支付|集分宝|如实描述 | Z25: 浙江杭州 | AA25: 童年梦之路 | AB25: 41902.902 | AC25: 1冠 | AD25: 4.6; 4.7; 4.6 | AE25: 37061 | AF25: 淘宝 | AG25: 0.9791 | AH25: 女装/女士精品 | AI25: 连衣裙 | AK25: 42244 | AL25: 0.91806713 | AM25: 5天3时52分16秒 | AN25: 五 | AO25: =HOUR(AL25) -> 22 | AP25: http://item.taobao.com/item.htm?id=520543428983
A26: 25 | B26: 第 1 页 第 25 位 | C26: 2015夏装大码女装超长两件套拼接款修身蕾丝中裙子印花雪纺连衣裙 | D26: 2YF001-6658 | E26: 128 | F26: 0.232 | G26: 29.7 | H26: 29.7 | I26: 24279 | J26: 5 | K26: 8239 | L26: 0.0096 | M26: 10091 | N26: 0.0089 | O26: 299702.7 | P26: 0.0054 | Q26: 19022 | R26: - | S26: - | T26: 1 | U26: 3941 | W26: 满3件，享包邮，送3元优惠券 | Z26: 浙江杭州 | AA26: 漫兰飘香旗舰店 | AB26: 41746.487 | AC26: 4冠 | AD26: 4.6; 4.6; 4.8 | AE26: 45399 | AF26: 天猫 | AG26: 1 | AH26: 女装/女士精品 | AI26: 连衣裙 | AK26: 42241 | AL26: 0.86111111 | AM26: 2天2时30分15秒 | AN26: 二 | AO26: =HOUR(AL26) -> 20 | AP26: http://item.taobao.com/item.htm?id=520518136294
A27: 26 | B27: 第 1 页 第 26 位 | C27: 彩黛妃2015春夏季新款女装性感气质短袖修身显瘦连衣裙韩版L0180 | D27: L0180 | E27: 128 | F27: 0.1547 | G27: 19.8 | H27: 19.8 | I27: 13683 | J27: 包邮 | K27: 7986 | L27: 0.0093 | M27: 10582 | N27: 0.0093 | O27: 209523.6 | P27: 0.0038 | Q27: 29880 | R27: - | S27: - | T27: 7 | U27: 9696 | Z27: 江苏宿迁 | AA27: 彩黛妃旗舰店 | AB27: 41723.451 | AC27: 1金冠 | AD27: 4.6; 4.6; 4.8 | AE27: 308260 | AF27: 天猫 | AG27: 1 | AH27: 女装/女士精品 | AI27: 连衣裙 | AK27: 42243 | AL27: 0.41960648 | AM27: 3天15时54分29秒 | AN27: 四 | AO27: =HOUR(AL27) -> 10 | AP27: http://item.taobao.com/item.htm?id=45315416266
A28: 27 | B28: 第 1 页 第 27 位 | C28: 2015夏季新款韩版女装休闲套装连衣裙裤短袖t恤雪纺衫短裙两件套 | E28: 78 | F28: 0.4872 | G28: 38 | H28: 38 | I28: 268870 | J28: 包邮 | K28: 7916 | L28: 0.0092 | M28: 9298 | N28: 0.0082 | O28: 353324 | P28: 0.0064 | Q28: 21184 | R28: 54126 | S28: 0.3914 | T28: 15 | U28: 3152 | Y28: 卖家承诺72小时内发货|7天无理由|蚂蚁花呗|信用卡支付|集分宝|如实描述 | Z28: 广东广州 | AA28: 雅丹娜韩版女装 | AB28: 41586.934 | AC28: 3冠 | AD28: 4.5; 4.5; 4.4 | AE28: 8607 | AF28: 淘宝 | AG28: 0.9494 | AH28: 女装/女士精品 | AI28: 连衣裙 | AK28: 42240 | AL28: 0.44097222 | AM28: 0.68420139 | AN28: 一 | AO28: =HOUR(AL28) -> 10 | AP28: http://item.taobao.com/item.htm?id=520090687820
A29: 28 | B29: 第 1 页 第 28 位 | C29: 1嫣洛-dl04新款2015夏装韩版女装圆领时髦女郎印花收腰连衣裙F-29 | E29: 110 | F29: 0.49 | G29: 53.9 | H29: 53.9 | I29: 3457 | J29: 包邮 | K29: 7704 | L29: 0.009 | M29: 8426 | N29: 0.0074 | O29: 454161.4 | P29: 0.0082 | Q29: 73858 | R29: 638129 | S29: 0.1157 | T29: 57 | U29: 11990 | Y29: 7天无理由|集分宝|支付宝支付|如实描述 | Z29: 浙江杭州 | AA29: 日韩女装专卖 | AB29: 39140.893 | AC29: 4金冠 | AD29: 4.6; 4.7; 4.6 | AE29: 4387178 | AF29: 淘宝 | AG29: 0.9879 | AH29: 女装/女士精品 | AI29: 连衣裙 | AK29: 42242 | AL29: 0.41898148 | AM29: 2天15时53分35秒 | AN29: 三 | AO29: =HOUR(AL29) -> 10 | AP29: http://item.taobao.com/item.htm?id=520232454502
A30: 29 | B30: 第 1 页 第 29 位 | C30: 2015夏季韩国碎花打底吊带裙女装修身背带短裙雪纺收腰显瘦连衣裙 | E30: 43 | F30: 0.4884 | G30: 21 | H30: 21 | I30: 17788 | J30: 包邮 | K30: 7573 | L30: 0.0088 | M30: 8794 | N30: 0.0078 | O30: 184674 | P30: 0.0033 | Q30: 26472 | R30: 28697 | S30: 0.9225 | T30: 7 | U30: 1892 | Y30: 7天无理由|集分宝|支付宝支付|如实描述 | Z30: 广东广州 | AA30: 小晗子家 | AB30: 41733.533 | AC30: 5钻 | AD30: 4.7; 4.7; 4.6 | AE30: 6583 | AF30: 淘宝 | AG30: 0.9777 | AH30: 女装/女士精品 | AI30: 连衣裙 | AK30: 42245 | AL30: 0.63194444 | AM30: 5天21时0分15秒 | AN30: 六 | AO30: =HOUR(AL30) -> 15 | AP30: http://item.taobao.com/item.htm?id=520063878818
